Workbook

Sheet ReadMe
A2: What is the purpose of test plan | B2: The purpose of a test plan for CAT bond portfolio testing is to ensure that the portfolio analysis system produces accurate, reliable, and consistent results under different conditions, portfolio compositions, and user actions before it is released to production.
A4: what is test strategy | B4: The testing strategy for the CAT Bond Bound Portfolio module is designed to validate Constraints, Guidelines, Expenses, Buy/sell Transaction date difference, Share %, Price (Premium, at Par, Discounted), Trade Date, Short - Term Deal and Run-Off Testing
A6: Prerequisite | B6: Prerequisites for testing are the conditions that must be met before testing can begin. They ensure that the environment, data, and application are ready for test execution.
B7: Prereq | C7: This is base data and is populated using the Excel driver sheet Peril_AAL_by_Instrument_v3.xlsm
B8: Prereq_result | C8: This is data from the testing environment and can be populated using the same excel driver sheet by changing the server, DB Name, and tab name
B9: Prereq stored Proc | C9: ARAPL_Configuration.dbo.usp_GetActivityRegionPerilAAL_DealAAL
B10: Pre req comparison check | C10: This pulls the unique Deals from Prereq_Result and comapre the AAL by deal agaisnt each deal in Base data and flag true or false. For us to proceed with test all the outcome should be true
A12: Testing EnvironmentPrep | B12: Need to clean up the Data tables and results tables of past test cases to avoid any confusion
B13: Clean up stored proc | C13: ARAPL_Configuration.dbo.usp_DeleteTestPortfolio
A15: Output | B15: Output file path Base data | C15: C:\Users\ARAPL_USER\Desktop\UI Testing\Portfolio Test\PortfolioTestCasefiles\Revised
B16: Output file name Base Data | C16: BoundReportOutput-07232026.xlsx
B17: Output file path UI Testing Data | C17: C:\Users\ARAPL_USER\Desktop\UI Testing\Portfolio Test\PortfolioTestCasefiles\Revised
B18: Output file name UI Testing data | C18: UITestingOutput.xlsx
B19: Comparison file path Base vs UI Testing | C19: C:\Users\ARAPL_USER\Desktop\UI Testing\Portfolio Test\PortfolioTestCasefiles\Revised
B20: Comparison file Name Base vs UI Testing | C20: PnL_Comparison_Driver

Sheet Prereq
A1: ILSName | B1: ILSInstrumentID | C1: ActivityID | D1: ScaleFactor | E1: DealAAL | F1: AAL_WWAP | G1: AAL_US Hurricanes | H1: AAL_Florida Hurricane | I1: AAL_Europe Tropical Cyclone | J1: AAL_Southeast Hurricane | K1: AAL_Texas Hurricane | L1: AAL_Gulf of Mexico WS | M1: AAL_Louisiana Hurricane | N1: AAL_SevereStorm | O1: AAL_US Severe Storm | P1: AAL_Other US WS | Q1: AAL_US WildFire | R1: AAL_Northeast Hurricane | S1: AAL_California Earthquake | T1: AAL_all other EQ | U1: AAL_Japan Typhoon | V1: AAL_All other WS | W1: AAL_Japan Earthquake | X1: AAL_US Earthquake xl CA | Y1: AAL_Europe Earthquake | Z1: AAL_US Winter Storm | AA1: AAL_Mexico Hurricane | AB1: AAL_South America Earthquake | AC1: AAL_Mexico Earthquake | AD1: AAL_US Inland Flood | AE1: AAL_Terrorism | AF1: AAL_0 | AG1: AAL_WildFire | AH1: AAL_InlandFlood | AI1: RunTimestamp
A2: CB-Herbie Re Ltd. Series 2025-1 Class A LMF USSCS | B2: 332 | C2: 332 | D2: 1 | E2: 9031965.7 | F2: 9031965.7 | G2: 5944624.5 | H2: 2951043.7 | I2: 860554.83 | J2: 750674.83 | K2: 726269.34 | L2: 705172.36 | M2: 536716.32 | N2: 514867.01 | O2: 514127.87 | P2: 489901.67 | Q2: 355839.5 | R2: 321562.62 | S2: 312584.16 | T2: 281901.92 | U2: 195124.13 | V2: 184457.07 | W2: 170327.58 | X2: 165119.53 | Y2: 70723.444 | Z2: 26566.272 | AA2: 19835.823 | AB2: 0 | AC2: 0 | AD2: 0 | AE2: 0 | AF2: 0 | AG2: 0 | AH2: 0 | AI2: 46230.712
A3: CB-FloodSmart Re Ltd. Series 2024-1 Class A Reset 2025_wLMF | B3: 333 | C3: 333 | D3: 1 | E3: 27054995 | F3: 27054995 | G3: 27007495 | H3: 18990519 | I3: 0 | J3: 215090.91 | K3: 673518.82 | L3: 6361573.2 | M3: 6314073.2 | N3: 0 | O3: 0 | P3: 539667.62 | Q3: 0 | R3: 227125.64 | S3: 0 | T3: 0 | U3: 0 | V3: 47500 | W3: 0 | X3: 0 | Y3: 0 | Z3: 0 | AA3: 0 | AB3: 0 | AC3: 0 | AD3: 0 | AE3: 0 | AF3: 0 | AG3: 0 | AH3: 0 | AI3: 46230.712
A4: CB-Meadows Ltd. Series 2025-1 Class A | B4: 334 | C4: 334 | D4: 1 | E4: 4303369.4 | F4: 4303369.4 | G4: 4093610 | H4: 4065395.6 | I4: 0 | J4: 17214.376 | K4: 0 | L4: 11000 | M4: 5500 | N4: 0 | O4: 0 | P4: 0 | Q4: 0 | R4: 0 | S4: 0 | T4: 0 | U4: 0 | V4: 209759.46 | W4: 0 | X4: 0 | Y4: 0 | Z4: 0 | AA4: 0 | AB4: 0 | AC4: 0 | AD4: 0 | AE4: 0 | AF4: 0 | AG4: 0 | AH4: 0 | AI4: 46230.712
A5: CB-Meadows Ltd. Series 2025-1 Class C | B5: 335 | C5: 335 | D5: 1 | E5: 851135.87 | F5: 851135.87 | G5: 834805.79 | H5: 660497.64 | I5: 0 | J5: 159308.15 | K5: 6000 | L5: 0 | M5: 0 | N5: 0 | O5: 0 | P5: 0 | Q5: 0 | R5: 9000 | S5: 0 | T5: 0 | U5: 0 | V5: 16330.076 | W5: 0 | X5: 0 | Y5: 0 | Z5: 0 | AA5: 0 | AB5: 0 | AC5: 0 | AD5: 0 | AE5: 0 | AF5: 0 | AG5: 0 | AH5: 0 | AI5: 46230.712
A6: CB-Blue Ridge Re Ltd. Series 2025-1 Class B | B6: 336 | C6: 336 | D6: 1 | E6: 7015056.7 | F6: 7015056.7 | G6: 6308007.4 | H6: 519284.24 | I6: 0 | J6: 5534425.1 | K6: 0 | L6: 7987.2473 | M6: 7987.2473 | N6: 693267.76 | O6: 693267.76 | P6: 110894.49 | Q6: 0 | R6: 135416.35 | S6: 0 | T6: 0 | U6: 0 | V6: 13781.498 | W6: 0 | X6: 0 | Y6: 0 | Z6: 0 | AA6: 0 | AB6: 0 | AC6: 0 | AD6: 0 | AE6: 0 | AF6: 0 | AG6: 0 | AH6: 0 | AI6: 46230.712
A7: CB-Blue Ridge Re Ltd. Series 2025-1 Class D | B7: 337 | C7: 337 | D7: 1 | E7: 5540731.5 | F7: 5540731.5 | G7: 2465634.5 | H7: 207225.61 | I7: 0 | J7: 2102218.1 | K7: 0 | L7: 17844.148 | M7: 10673.801 | N7: 2360164.4 | O7: 2360164.4 | P7: 50247.098 | Q7: 0 | R7: 88099.561 | S7: 0 | T7: 0 | U7: 0 | V7: 15229.508 | W7: 0 | X7: 0 | Y7: 0 | Z7: 699703.1 | AA7: 0 | AB7: 0 | AC7: 0 | AD7: 0 | AE7: 0 | AF7: 0 | AG7: 0 | AH7: 0 | AI7: 46230.712
A8: CB-Aquila Re I Ltd. Series 2023-1 Class A-1 Reset 2025 | B8: 1 | C8: 1 | D8: 1 | E8: 275718.11 | F8: 275718.11 | G8: 273060.2 | H8: 28248.565 | I8: 0 | J8: 121151.12 | K8: 3155.5444 | L8: 0 | M8: 0 | N8: 0 | O8: 0 | P8: 79313.225 | Q8: 0 | R8: 41191.748 | S8: 2657.9093 | T8: 0 | U8: 0 | V8: 0 | W8: 0 | X8: 0 | Y8: 0 | Z8: 0 | AA8: 0 | AB8: 0 | AC8: 0 | AD8: 0 | AE8: 0 | AF8: 0 | AG8: 0 | AH8: 0 | AI8: 46230.712
A9: CB-Aquila Re I Ltd. Series 2023-1 Class B-1 Reset 2025 | B9: 2 | C9: 2 | D9: 1 | E9: 1328819.4 | F9: 1328819.4 | G9: 1222463.8 | H9: 129091.3 | I9: 0 | J9: 504837.23 | K9: 87250.696 | L9: 7892.9001 | M9: 7892.9001 | N9: 39941.979 | O9: 39941.979 | P9: 304566.15 | Q9: 2614.8826 | R9: 188825.54 | S9: 60725.903 | T9: 92.340196 | U9: 0 | V9: 0 | W9: 0 | X9: 2980.4966 | Y9: 0 | Z9: 0 | AA9: 0 | AB9: 0 | AC9: 0 | AD9: 0 | AE9: 0 | AF9: 0 | AG9: 0 | AH9: 0 | AI9: 46230.712
A10: CB-Aquila Re I Ltd. Series 2023-1 Class C-1 Reset 2025 | B10: 3 | C10: 3 | D10: 1 | E10: 1907171.6 | F10: 1907171.6 | G10: 1691057.1 | H10: 180654.64 | I10: 0 | J10: 692687.44 | K10: 163786.18 | L10: 14817.722 | M10: 14817.722 | N10: 82046.247 | O10: 82046.247 | P10: 375396.65 | Q10: 8428.5424 | R10: 263714.51 | S10: 109810.07 | T10: 2743.3592 | U10: 0 | V10: 0 | W10: 0 | X10: 8807.7639 | Y10: 0 | Z10: 4278.4308 | AA10: 0 | AB10: 0 | AC10: 0 | AD10: 0 | AE10: 0 | AF10: 0 | AG10: 0 | AH10: 0 | AI10: 46230.712
A11: CB-Aquila Re I Ltd. Series 2024-1 Class A-1 Reset 2025 | B11: 4 | C11: 4 | D11: 1 | E11: 818433.86 | F11: 818433.86 | G11: 806805.51 | H11: 82896.259 | I11: 0 | J11: 362088.89 | K11: 13805.507 | L11: 0 | M11: 0 | N11: 0 | O11: 0 | P11: 227259.42 | Q11: 0 | R11: 120755.44 | S11: 11628.353 | T11: 0 | U11: 0 | V11: 0 | W11: 0 | X11: 0 | Y11: 0 | Z11: 0 | AA11: 0 | AB11: 0 | AC11: 0 | AD11: 0 | AE11: 0 | AF11: 0 | AG11: 0 | AH11: 0 | AI11: 46230.712
A12: CB-Aquila Re I Ltd. Series 2024-1 Class B-1 Reset 2025 | B12: 5 | C12: 5 | D12: 1 | E12: 1280820 | F12: 1280820 | G12: 1155318.6 | H12: 122982.92 | I12: 0 | J12: 464775.75 | K12: 101137.17 | L12: 9681.9574 | M12: 9681.9574 | N12: 48995.494 | O12: 48995.494 | P12: 276637.12 | Q12: 3207.5893 | R12: 180103.67 | S12: 69529.01 | T12: 113.27064 | U12: 0 | V12: 0 | W12: 0 | X12: 3656.0757 | Y12: 0 | Z12: 0 | AA12: 0 | AB12: 0 | AC12: 0 | AD12: 0 | AE12: 0 | AF12: 0 | AG12: 0 | AH12: 0 | AI12: 46230.712
A13: CB-123 Lights Re Ltd. Series 2025-1 Class A | B13: 6 | C13: 6 | D13: 1 | E13: 2016418.3 | F13: 2016418.3 | G13: 0 | H13: 0 | I13: 0 | J13: 0 | K13: 0 | L13: 0 | M13: 0 | N13: 0 | O13: 0 | P13: 0 | Q13: 2016418.3 | R13: 0 | S13: 0 | T13: 0 | U13: 0 | V13: 0 | W13: 0 | X13: 0 | Y13: 0 | Z13: 0 | AA13: 0 | AB13: 0 | AC13: 0 | AD13: 0 | AE13: 0 | AF13: 0 | AG13: 0 | AH13: 0 | AI13: 46230.712
... A329: CB-Res Re 2025 Ltd. Series 2025-II Class 2 | B329: 320 | C329: 320 | D329: 1 | E329: 14412327 | F329: 14412327 | G329: 10681655 | H329: 3525686.6 | I329: 0 | J329: 2373587.5 | K329: 1227610.1 | L329: 987053.28 | M329: 891347.11 | N329: 1850982.2 | O329: 1850982.2 | P329: 1468688.9 | Q329: 1633086.3 | R329: 1099028.6 | S329: 142394.16 | T329: 37710.762 | U329: 0 | V329: 4339.6246 | W329: 0 | X329: 51532.456 | Y329: 0 | Z329: 10626.109 | AA329: 0 | AB329: 0 | AC329: 0 | AD329: 0 | AE329: 0 | AF329: 0 | AG329: 0 | AH329: 0 | AI329: 46230.73

Sheet Prereq_result
A1: ILSName | B1: ILSInstrumentID | C1: ActivityID | D1: ScaleFactor | E1: DealAAL | F1: AAL_WWAP | G1: AAL_US Hurricanes | H1: AAL_Florida Hurricane | I1: AAL_Gulf of Mexico WS | J1: AAL_Texas Hurricane | K1: AAL_Mexico Hurricane | L1: AAL_All other WS | M1: AAL_all other EQ | N1: AAL_Mexico Earthquake | O1: AAL_South America Earthquake | P1: AAL_Louisiana Hurricane | Q1: AAL_Europe Earthquake | R1: AAL_US Winter Storm | S1: AAL_US WildFire | T1: AAL_US Severe Storm | U1: AAL_US Inland Flood | V1: AAL_Southeast Hurricane | W1: AAL_Northeast Hurricane | X1: AAL_Other US WS | Y1: AAL_California Earthquake | Z1: AAL_US Earthquake xl CA | AA1: AAL_Japan Typhoon | AB1: AAL_Japan Earthquake | AC1: AAL_WildFire | AD1: AAL_InlandFlood | AE1: AAL_SevereStorm | AF1: AAL_Terrorism | AG1: AAL_Europe Tropical Cyclone | AH1: AAL_0 | AI1: RunTimestamp
A2: CB-Lightning Re Ltd. Series 2023-1 Class A Reset 2025 | B2: 10 | C2: 10 | D2: 1 | E2: 13448322 | F2: 13448322 | G2: 13433758 | H2: 13393320 | I2: 27835.404 | J2: 12601.981 | K2: 12027.441 | L2: 2537.1371 | M2: 0 | N2: 0 | O2: 0 | P2: 0 | Q2: 0 | R2: 0 | S2: 0 | T2: 0 | U2: 0 | V2: 0 | W2: 0 | X2: 0 | Y2: 0 | Z2: 0 | AA2: 0 | AB2: 0 | AC2: 0 | AD2: 0 | AE2: 0 | AF2: 0 | AG2: 0 | AH2: 0 | AI2: 46226.615
A3: CB-Recoletos Re DAC Series 2024-1 Class A | B3: 11 | C3: 11 | D3: 1 | E3: 3276270.8 | F3: 3276270.8 | G3: 3276270.8 | H3: 596403.36 | I3: 65221.972 | J3: 442904.24 | K3: 0 | L3: 0 | M3: 0 | N3: 0 | O3: 0 | P3: 64973.966 | Q3: 0 | R3: 0 | S3: 0 | T3: 0 | U3: 0 | V3: 596934.52 | W3: 582983.13 | X3: 991823.59 | Y3: 0 | Z3: 0 | AA3: 0 | AB3: 0 | AC3: 0 | AD3: 0 | AE3: 0 | AF3: 0 | AG3: 0 | AH3: 0 | AI3: 46226.615
A4: CB-Stabilitas Re Ltd. Series 2023-1 Class A Reset 2025 | B4: 12 | C4: 12 | D4: 1 | E4: 3515844.9 | F4: 3515844.9 | G4: 2364593.6 | H4: 1423618.9 | I4: 24162.023 | J4: 153004.34 | K4: 2550.3091 | L4: 10000 | M4: 14402.831 | N4: 0 | O4: 0 | P4: 14807.618 | Q4: 0 | R4: 0 | S4: 0 | T4: 0 | U4: 0 | V4: 159192.41 | W4: 159663.32 | X4: 444952.61 | Y4: 1111808.5 | Z4: 12489.676 | AA4: 0 | AB4: 0 | AC4: 0 | AD4: 0 | AE4: 0 | AF4: 0 | AG4: 0 | AH4: 0 | AI4: 46226.615
A5: CB-Cape Lookout Re Ltd. Series 2023-1 Class A Reset 2025 | B5: 13 | C5: 13 | D5: 1 | E5: 15581003 | F5: 15581003 | G5: 15519078 | H5: 1620202.2 | I5: 0 | J5: 0 | K5: 23016.746 | L5: 38908.585 | M5: 0 | N5: 0 | O5: 0 | P5: 0 | Q5: 0 | R5: 0 | S5: 0 | T5: 0 | U5: 0 | V5: 12574452 | W5: 901880.99 | X5: 422542.85 | Y5: 0 | Z5: 0 | AA5: 0 | AB5: 0 | AC5: 0 | AD5: 0 | AE5: 0 | AF5: 0 | AG5: 0 | AH5: 0 | AI5: 46226.616
A6: CB-Cape Lookout Re Ltd. Series 2024-1 Class A Reset 2025 | B6: 14 | C6: 14 | D6: 1 | E6: 26866076 | F6: 26866076 | G6: 26681868 | H6: 2742899.2 | I6: 0 | J6: 0 | K6: 45000 | L6: 139207.52 | M6: 0 | N6: 0 | O6: 0 | P6: 0 | Q6: 0 | R6: 0 | S6: 0 | T6: 0 | U6: 0 | V6: 21302653 | W6: 1845751.6 | X6: 790564.64 | Y6: 0 | Z6: 0 | AA6: 0 | AB6: 0 | AC6: 0 | AD6: 0 | AE6: 0 | AF6: 0 | AG6: 0 | AH6: 0 | AI6: 46226.616
A7: CB-Ashera Re Ltd. Series 2024-1 Class A Reset 2025 | B7: 15 | C7: 15 | D7: 1 | E7: 3958390.2 | F7: 3958390.2 | G7: 3820562.2 | H7: 1964985 | I7: 34179.618 | J7: 248529.45 | K7: 0 | L7: 0 | M7: 7926.6962 | N7: 0 | O7: 0 | P7: 33049.325 | Q7: 0 | R7: 0 | S7: 0 | T7: 0 | U7: 0 | V7: 311107.61 | W7: 289426.69 | X7: 972333.79 | Y7: 117134.98 | Z7: 12766.367 | AA7: 0 | AB7: 0 | AC7: 0 | AD7: 0 | AE7: 0 | AF7: 0 | AG7: 0 | AH7: 0 | AI7: 46226.616
A8: CB-Ramble Re Ltd. Series 2024-1 Class A Reset 2025 | B8: 16 | C8: 16 | D8: 1 | E8: 3524638.6 | F8: 3524638.6 | G8: 1704435.6 | H8: 64955.913 | I8: 0 | J8: 0 | K8: 0 | L8: 0 | M8: 204112.62 | N8: 0 | O8: 0 | P8: 0 | Q8: 0 | R8: 0 | S8: 0 | T8: 0 | U8: 0 | V8: 64880.881 | W8: 587651.69 | X8: 986947.1 | Y8: 1147273.6 | Z8: 468816.74 | AA8: 0 | AB8: 0 | AC8: 0 | AD8: 0 | AE8: 0 | AF8: 0 | AG8: 0 | AH8: 0 | AI8: 46226.616
A9: CB-Galileo Re Ltd. Series 2023-1 Class A Reset 2025 | B9: 17 | C9: 17 | D9: 1 | E9: 5017850 | F9: 5017850 | G9: 4098554.8 | H9: 1947471.6 | I9: 177738.06 | J9: 537826.15 | K9: 0 | L9: 0 | M9: 226445.82 | N9: 0 | O9: 0 | P9: 166206.67 | Q9: 0 | R9: 0 | S9: 0 | T9: 0 | U9: 0 | V9: 395832.65 | W9: 234939.19 | X9: 804747.19 | Y9: 359350.49 | Z9: 333498.84 | AA9: 0 | AB9: 0 | AC9: 0 | AD9: 0 | AE9: 0 | AF9: 0 | AG9: 0 | AH9: 0 | AI9: 46226.616

Sheet Prereq_Comparison
A1: {=_xlfn.UNIQUE(Prereq_result!A:C)} -> ILSName | B1: ILSInstrumentID | C1: ActivityID | D1: GR_AAL | E1: Flag
A2: CB-Lightning Re Ltd. Series 2023-1 Class A Reset 2025 | B2: 10 | C2: 10 | D2: =VLOOKUP(A2,Prereq_result!$A:$E,5,0)/VLOOKUP(A2,Prereq!$A:$E,5,0) -> 1 | E2: =IF(D2=100%, TRUE,FALSE) -> TRUE | G2: Proceed Teting | H2: =AND(E2:E9) -> TRUE
A3: CB-Recoletos Re DAC Series 2024-1 Class A | B3: 11 | C3: 11 | D3: =VLOOKUP(A3,Prereq_result!$A:$E,5,0)/VLOOKUP(A3,Prereq!$A:$E,5,0) -> 1 | E3: =IF(D3=100%, TRUE,FALSE) -> TRUE
A4: CB-Stabilitas Re Ltd. Series 2023-1 Class A Reset 2025 | B4: 12 | C4: 12 | D4: =VLOOKUP(A4,Prereq_result!$A:$E,5,0)/VLOOKUP(A4,Prereq!$A:$E,5,0) -> 1 | E4: =IF(D4=100%, TRUE,FALSE) -> TRUE
A5: CB-Cape Lookout Re Ltd. Series 2023-1 Class A Reset 2025 | B5: 13 | C5: 13 | D5: =VLOOKUP(A5,Prereq_result!$A:$E,5,0)/VLOOKUP(A5,Prereq!$A:$E,5,0) -> 1 | E5: =IF(D5=100%, TRUE,FALSE) -> TRUE
A6: CB-Cape Lookout Re Ltd. Series 2024-1 Class A Reset 2025 | B6: 14 | C6: 14 | D6: =VLOOKUP(A6,Prereq_result!$A:$E,5,0)/VLOOKUP(A6,Prereq!$A:$E,5,0) -> 1 | E6: =IF(D6=100%, TRUE,FALSE) -> TRUE
A7: CB-Ashera Re Ltd. Series 2024-1 Class A Reset 2025 | B7: 15 | C7: 15 | D7: =VLOOKUP(A7,Prereq_result!$A:$E,5,0)/VLOOKUP(A7,Prereq!$A:$E,5,0) -> 1 | E7: =IF(D7=100%, TRUE,FALSE) -> TRUE
A8: CB-Ramble Re Ltd. Series 2024-1 Class A Reset 2025 | B8: 16 | C8: 16 | D8: =VLOOKUP(A8,Prereq_result!$A:$E,5,0)/VLOOKUP(A8,Prereq!$A:$E,5,0) -> 1 | E8: =IF(D8=100%, TRUE,FALSE) -> TRUE
A9: CB-Galileo Re Ltd. Series 2023-1 Class A Reset 2025 | B9: 17 | C9: 17 | D9: =VLOOKUP(A9,Prereq_result!$A:$E,5,0)/VLOOKUP(A9,Prereq!$A:$E,5,0) -> 1 | E9: =IF(D9=100%, TRUE,FALSE) -> TRUE
A10: 0 | B10: 0 | C10: 0

Sheet 00_Instructions
A1: PORTFOLIO FLOW — TEST CASE WORKBOOK
A2: PURPOSE | B2: Drive automated Playwright tests from this Excel. Developer fills data; tester just runs pytest.
A4: SHEETS
A5: 01_Portfolio | B5: CRUD tests for Portfolio popup
A6: 02_Transaction | B6: CRUD tests for Transaction edit popup (used BEFORE portfolio flow)
A7: 03_Mapping | B7: Tests for Transaction → ILS Deal Mapping popup
A8: 04_Portfolio_Guidelines | B8: CRUD tests for Portfolio Guidelines grid + edit popup
A9: 05_Pricing_Parameters | B9: Tests for Portfolio Pricing Parameters popup
A10: 06_Portfolio_Expenses | B10: Tests for Portfolio Expenses popup
A11: 07_Bound_Portfolio | B11: Tests for Bound Portfolio popup
A12: 08_Bound_Portfolio_Details | B12: Tests for Bound Portfolio Details popup
A13: 09_Bound_Report_Filter | B13: Tests for Bound Report Filter popup
A14: Lookups | B14: Hidden sheet — dropdown source lists. Do NOT edit.
A16: COLUMN COLOUR GUIDE
A17: Yellow background | B17: ★ Required field — must be filled
A18: Grey background | B18: Optional field — leave blank to skip
A19: Gold background | B19: Auto-populated / read-only field
A20: Green Actual Result | B20: Test PASSED
A21: Red Actual Result | B21: Test FAILED
A23: ROW GUIDE (rows 1-5 in each sheet)
A24: Row 1 — Title banner | B24: Screen name and purpose
A25: Row 2 — Section groups | B25: Colour-coded grouping of related columns
A26: Row 3 — Column header | B26: Human-readable field label
A27: Row 4 — Field name | B27: Exact JSON popup field name in [brackets]
A28: Row 5 — Required? | B28: ★ Required or Optional
A29: Row 6+ — Data rows | B29: One test case per row
A31: HOW TO ADD MORE TEST CASES
A32: Step 1 | B32: Copy the sample data row (row 6) downward
A33: Step 2 | B33: Change TestCaseID, Action, and field values
A34: Step 3 | B34: Use the dropdown arrows in each cell for valid values
A35: Step 4 | B35: Run: pytest tests/test_portfolio_flow.py -v --html=reports/report.html
A37: NOTES
A38: Idempotent | B38: Tests check if data already exists before adding — safe to re-run
A39: Order matters | B39: Run Add before Edit; Edit before Delete within the same screen
A40: Dates | B40: Enter dates as YYYY-MM-DD e.g. 2025-01-01
A41: Numbers | B41: Enter numbers without $ or commas e.g. 10000000

Sheet 01_Portfolio
A1: SCREEN 1 — PORTFOLIO
A2: ► Test Control | C2: ► Portfolio Details
A3: Test Case ID | B3: Action | C3: Portfolio Name | D3: Vendor | E3: Create Date | F3: Run DateTime | G3: Add Guidelines | H3: Add Expenses | I3: Add Transactions | J3: Run This Test Case | K3: Notes | L3: Notes Taken | M3: Actual Result
A4: [Auto-generated] | B4: [Add / Edit / Delete] | C4: [Name] | D4: [Vendor] | E4: [CreateDate] | F4: [—] | J4: [RunTestCase] | K4: [—] | M4: [—]
A5: ★ Required | B5: ★ Required | C5: ★ Required | D5: ★ Required | E5: Optional | F5: Read-only | J5: Optional | K5: Optional | M5: Read-only
A6: TC_PF_001 | B6: Add | C6: Test_Portfolio_001 | D6: AIR | G6: Yes | H6: Yes | I6: Yes | J6: Yes | K6: Portfolio 'Test_Portfolio_001' added | L6: Worldwide data with 5 transactions
A7: TC_PF_002 | B7: Add | C7: Test_Portfolio_001 | D7: AIR | G7: Yes | H7: No | I7: No | J7: Yes | K7: Portfolio 'Test_Portfolio_001' already existed | L7: Change Guidelines
A8: TC_PF_003 | B8: Add | C8: Test_Portfolio_001 | D8: AIR | G8: No | H8: No | I8: No | J8: Yes | K8: Unhandled exception: TimeoutError: Locator.dblclick: Timeout 30000ms exceeded. Call log: - waiting for locator("[role=\"gridcell\"]").filter(has_text="Test_Portfolio_001").first | L8: Changed Notional and deployed AUM twice as test case 1
A9: TC_PF_004 | B9: Add | C9: Test_Portfolio_002 | D9: AIR | G9: Yes | H9: Yes | I9: Yes | J9: Yes | K9: Portfolio 'Test_Portfolio_002' added | L9: CA EQ
A10: TC_PF_005 | B10: Add | C10: Test_Portfolio_003 | D10: AIR | G10: Yes | H10: Yes | I10: Yes | J10: Yes | K10: Unhandled exception: AssertionError: Could not navigate to Portfolio Overview screen. Check sidebar button selector — look at the actual sidebar button ID in your app. | L10: US only
A11: TC_PF_006 | B11: Add | C11: Test_Portfolio_004 | D11: AIR | G11: Yes | H11: Yes | I11: Yes | J11: Yes | K11: Unhandled exception: AssertionError: Could not navigate to Portfolio Overview screen. Check sidebar button selector — look at the actual sidebar button ID in your app. | L11: FL only
A12: TC_PF_007 | B12: Add | C12: Test_Portfolio_001 | D12: AIR | G12: Yes | H12: Yes | I12: Yes | J12: Yes | K12: Unhandled exception: AssertionError: Could not navigate to Portfolio Overview screen. Check sidebar button selector — look at the actual sidebar button ID in your app. | L12: Guidelines failures for each guidelines
A13: TC_PF_008 | B13: Add | C13: Test_Portfolio_002 | D13: AIR | G13: No | H13: Yes | I13: No | J13: Yes | K13: Unhandled exception: AssertionError: Could not navigate to Portfolio Overview screen. Check sidebar button selector — look at the actual sidebar button ID in your app. | L13: Modify expenses
A14: TC_PF_009 | B14: Add | C14: Test_Portfolio_002 | D14: AIR | G14: No | H14: Yes | I14: No | J14: Yes | K14: Unhandled exception: AssertionError: Could not navigate to Portfolio Overview screen. Check sidebar button selector — look at the actual sidebar button ID in your app. | L14: Modify expenses
A15: TC_PF_010 | B15: Add | C15: Test_Portfolio_002 | D15: AIR | G15: No | H15: Yes | I15: No | J15: Yes | K15: Unhandled exception: AssertionError: Could not navigate to Portfolio Overview screen. Check sidebar button selector — look at the actual sidebar button ID in your app. | L15: Modify expenses
A16: TC_PF_011 | B16: Add | C16: Test_Portfolio_002 | D16: AIR | G16: No | H16: Yes | I16: No | J16: Yes | K16: Unhandled exception: AssertionError: Could not navigate to Portfolio Overview screen. Check sidebar button selector — look at the actual sidebar button ID in your app. | L16: Modify expenses
A17: TC_PF_012 | B17: Add | C17: Test_Portfolio_002 | D17: AIR | G17: No | H17: Yes | I17: No | J17: Yes | K17: Unhandled exception: AssertionError: Could not navigate to Portfolio Overview screen. Check sidebar button selector — look at the actual sidebar button ID in your app. | L17: Modify expenses
... A29: TC_PF_024 | B29: Add | C29: Test_Portfolio_012 | D29: AIR | G29: Yes | H29: Yes | I29: Yes | J29: Yes | K29: Unhandled exception: AssertionError: Could not navigate to Portfolio Overview screen. Check sidebar button selector — look at the actual sidebar button ID in your app. | L29: Base case
A30: TC_PF_025 | B30: Add | C30: Test_Portfolio_013 | D30: AIR | G30: Yes | H30: Yes | I30: Yes | J30: Yes | L30: Vary share/price and buy/sell date - Half Postiton - Reduce the share to 50% for each bond, dates are same
A31: TC_PF_026 | B31: Add | C31: Test_Portfolio_014 | D31: AIR | G31: Yes | H31: Yes | I31: Yes | J31: Yes | L31: Vary share/price and buy/sell date - Same share but move the buy date to 6 months later for all bonds
A32: TC_PF_027 | B32: Add | C32: Test_Portfolio_015 | D32: AIR | G32: Yes | H32: Yes | I32: Yes | J32: Yes | L32: Vary share/price and buy/sell date - Large Trade - Performance and overflow testing Large Trade 10*quantity
A33: TC_PF_028 | B33: Add | C33: Test_Portfolio_016 | D33: AIR | G33: Yes | H33: Yes | I33: Yes | J33: Yes | L33: Vary share/price and buy/sell date -Decrese and Increase the price of all Bonds
A34: TC_PF_029 | B34: Add | C34: Test_Portfolio_017 | D34: AIR | G34: Yes | H34: Yes | I34: Yes | J34: Yes | L34: Vary share/price and buy/sell date - at Par
A35: TC_PF_030 | B35: Add | C35: Test_Portfolio_018 | D35: AIR | G35: Yes | H35: Yes | I35: Yes | J35: Yes | L35: Vary share/price and buy/sell date - Discounted price
A36: TC_PF_031 | B36: Add | C36: Test_Portfolio_019 | D36: AIR | G36: Yes | H36: Yes | I36: Yes | J36: Yes | L36: Vary share/price and buy/sell date - Future Buy date
A37: TC_PF_032 | B37: Add | C37: Test_Portfolio_020 | D37: AIR | G37: Yes | H37: Yes | I37: Yes | J37: Yes | L37: Short term deals < 1 year by Peril - Eq
A38: TC_PF_033 | B38: Add | C38: Test_Portfolio_021 | D38: AIR | G38: Yes | H38: Yes | I38: Yes | J38: Yes | L38: Short term deals < 1 year by Peril - HU
A39: TC_PF_034 | B39: Add | C39: Test_Portfolio_022 | D39: AIR | G39: Yes | H39: Yes | I39: Yes | J39: Yes | L39: Run off only - Expiration of deals becomes very important - Eq deals with run off -1
A40: TC_PF_035 | B40: Add | C40: Test_Portfolio_023 | D40: AIR | G40: Yes | H40: Yes | I40: Yes | J40: Yes | L40: Run off only - Expiration of deals becomes very important - WS deals with run off -1

Sheet 04_Portfolio_Guidelines
A1: SCREEN 4 — PORTFOLIO GUIDELINES
A2: ► Test Control | C2: ► Context | D2: ► Constraint (Required) | F2: ► Limits & Settings
A3: Test Case ID | B3: Action | C3: Portfolio ID | D3: Constraint Type | E3: Constraint Name | F3: Single Limit | G3: Max Limit | H3: Loss Type | I3: Return Period (Yrs) | J3: Notes
A4: [Auto-generated] | B4: [Add / Edit / Delete] | C4: [PortfolioId] | D4: [ConstraintType] | E4: [ConstraintName] | F4: [SingleLimit] | G4: [MaxLimit] | H4: [LossType] | I4: [ReturnPeriod] | J4: [—]
A5: ★ Required | B5: ★ Required | C5: ★ Required | D5: ★ Required | E5: Optional | F5: Optional | G5: Optional | H5: Optional | I5: Optional | J5: Optional
A6: TC_PF_001 | B6: Add | C6: 1 | D6: Cedant | E6: Single Cedent (including business fronted by Allianz Risk Transfer) | F6: 0 | G6: 0.15 | I6: 0
A7: TC_PF_001 | B7: Add | C7: 1 | D7: Issuer | E7: CAT Bond | F7: 0 | G7: 0.3 | I7: 0
A8: TC_PF_001 | B8: Add | C8: 1 | D8: Single | E8: CAT Bond | F8: 0 | G8: 0.05 | I8: 0
A9: TC_PF_001 | B9: Add | C9: 1 | D9: Single | E9: Cash | F9: 0 | G9: 0 | I9: 0
A10: TC_PF_001 | B10: Add | C10: 1 | D10: PerilRegion | E10: US Hurricanes | F10: 0 | G10: 0.35 | H10: OEP | I10: 100
A11: TC_PF_001 | B11: Add | C11: 1 | D11: PerilRegion | E11: Florida Hurricane | F11: 0 | G11: 0.3 | H11: OEP | I11: 100
A12: TC_PF_001 | B12: Add | C12: 1 | D12: PerilRegion | E12: Gulf of Mexico WS | F12: 0 | G12: 0.3 | H12: OEP | I12: 100
A13: TC_PF_001 | B13: Add | C13: 1 | D13: PerilRegion | E13: Japan Typhoon | F13: 0 | G13: 0.3 | H13: OEP | I13: 100
A14: TC_PF_001 | B14: Add | C14: 1 | D14: PerilRegion | E14: Texas Hurricane | F14: 0 | G14: 0.3 | H14: OEP | I14: 100
A15: TC_PF_001 | B15: Add | C15: 1 | D15: PerilRegion | E15: California Earthquake | F15: 0 | G15: 0.2 | H15: OEP | I15: 100
A16: TC_PF_001 | B16: Add | C16: 1 | D16: PerilRegion | E16: Japan Earthquake | F16: 0 | G16: 0.2 | H16: OEP | I16: 100
A17: TC_PF_001 | B17: Add | C17: 1 | D17: PerilRegion | E17: All other WS | F17: 0 | G17: 0.3 | H17: OEP | I17: 100
A18: TC_PF_001 | B18: Add | C18: 1 | D18: PerilRegion | E18: all other EQ | F18: 0 | G18: 0.2 | H18: OEP | I18: 100
A19: TC_PF_001 | B19: Add | C19: 1 | D19: PerilRegion | E19: WildFire | F19: 0 | G19: 0.15 | H19: OEP | I19: 100
A20: TC_PF_001 | B20: Add | C20: 1 | D20: PerilRegion | E20: InlandFlood | F20: 0 | G20: 0.15 | H20: OEP | I20: 100
A21: TC_PF_001 | B21: Add | C21: 1 | D21: PerilRegion | E21: SevereStorm | F21: 0 | G21: 0.15 | H21: OEP | I21: 100
... A45: TC_PF_001 | B45: Add | C45: 1 | D45: PerilRegion | E45: US Inland Flood | F45: 0 | G45: 0.35 | H45: AEP | I45: 500
A46: TC_PF_001 | B46: Add | C46: 1 | D46: ReinsuranceType | E46: CAT Bond | F46: 0 | G46: 0.5 | I46: 0
A47: TC_PF_002 | B47: Add | C47: 1 | D47: Issuer | E47: CAT Bond | F47: 0 | G47: 0.3 | I47: 0
A48: TC_PF_002 | B48: Add | C48: 1 | D48: Single | E48: CAT Bond | F48: 0 | G48: 0.05 | I48: 0
A49: TC_PF_002 | B49: Add | C49: 1 | D49: Single | E49: Cash | F49: 0 | G49: 0 | I49: 0
A50: TC_PF_002 | B50: Add | C50: 1 | D50: PerilRegion | E50: US Hurricanes | F50: 0 | G50: 0.35 | H50: OEP | I50: 100
A51: TC_PF_002 | B51: Add | C51: 1 | D51: PerilRegion | E51: Florida Hurricane | F51: 0 | G51: 0.3 | H51: OEP | I51: 100
A52: TC_PF_002 | B52: Add | C52: 1 | D52: PerilRegion | E52: Gulf of Mexico WS | F52: 0 | G52: 0.3 | H52: OEP | I52: 100
A53: TC_PF_002 | B53: Add | C53: 1 | D53: PerilRegion | E53: Texas Hurricane | F53: 0 | G53: 0.3 | H53: OEP | I53: 100
A54: TC_PF_002 | B54: Add | C54: 1 | D54: PerilRegion | E54: All other WS | F54: 0 | G54: 0.3 | H54: OEP | I54: 100
A55: TC_PF_002 | B55: Add | C55: 1 | D55: PerilRegion | E55: US Hurricanes | F55: 0 | G55: 0.5 | H55: AEP | I55: 500
A56: TC_PF_002 | B56: Add | C56: 1 | D56: PerilRegion | E56: Florida Hurricane | F56: 0 | G56: 0.5 | H56: AEP | I56: 500
A57: TC_PF_002 | B57: Add | C57: 1 | D57: PerilRegion | E57: Gulf of Mexico WS | F57: 0 | G57: 0.5 | H57: AEP | I57: 500
A58: TC_PF_002 | B58: Add | C58: 1 | D58: PerilRegion | E58: Texas Hurricane | F58: 0 | G58: 0.5 | H58: AEP | I58: 500
A59: TC_PF_002 | B59: Add | C59: 1 | D59: PerilRegion | E59: All other WS | F59: 0 | G59: 0.5 | H59: AEP | I59: 500
A60: TC_PF_002 | B60: Add | C60: 1 | D60: ReinsuranceType | E60: CAT Bond | F60: 0 | G60: 0.5 | I60: 0
A61: TC_PF_004 | B61: Add | C61: 1 | D61: Cedant | E61: Single Cedent (including business fronted by Allianz Risk Transfer) | F61: 0 | G61: 0.15 | I61: 0
A62: TC_PF_004 | B62: Add | C62: 1 | D62: Issuer | E62: CAT Bond | F62: 0 | G62: 0.3 | I62: 0
A63: TC_PF_004 | B63: Add | C63: 1 | D63: Single | E63: CAT Bond | F63: 0 | G63: 0.05 | I63: 0
...

Sheet 06_Portfolio_Expenses
A1: SCREEN 6 — PORTFOLIO EXPENSES
A2: ► Test Control | C2: ► Expense Details
A3: Test Case ID | B3: Action | C3: Management Fee | D3: Carry | E3: Hurdle Type | F3: Hurdle | G3: Fronting Fee | H3: Acquisition Expense | I3: FET | J3: Investment Income | K3: Operating Expenses | L3: Risk Free Rate | M3: QS Attritional LR US Wind | N3: QS Attritional LR Worldwide | O3: Pro Forma Rate Change | P3: Notes
A4: [Auto-generated] | B4: [Save / Delete] | C4: [ManagementFee] | D4: [Carry] | E4: [HurdleType] | F4: [Hurdle] | G4: [FrontingFee] | H4: [AcquisitionExpense] | I4: [FET] | J4: [InvestmentIncome] | K4: [OpsExpenses] | L4: [RiskFreeRate] | M4: [QSAttritionalLRUSWind] | N4: [QSAttritionalLRWorldwide] | O4: [ProFormaRateChange] | P4: [—]
A5: ★ Required | B5: ★ Required | C5: Optional | D5: Optional | E5: Optional | F5: Optional | G5: Optional | H5: Optional | I5: Optional | J5: Optional | K5: Optional | L5: Optional | M5: Optional | N5: Optional | O5: Optional | P5: Optional
A6: TC_PF_001 | B6: Add | C6: 0.012 | D6: 0 | E6: Hard | F6: 0 | G6: 0 | H6: 0 | I6: 0 | J6: 0 | K6: 0.0038 | L6: 0.0387 | M6: 0 | N6: 0 | O6: 0
A7: TC_PF_002 | B7: Add | C7: 0.012 | D7: 0 | E7: Hard | F7: 0 | G7: 0 | H7: 0 | I7: 0 | J7: 0 | K7: 0.0038 | L7: 0.0387 | M7: 0 | N7: 0 | O7: 0
A8: TC_PF_003 | B8: Add | C8: 0.012 | D8: 0 | E8: Hard | F8: 0 | G8: 0 | H8: 0 | I8: 0 | J8: 0 | K8: 0.0038 | L8: 0.0387 | M8: 0 | N8: 0 | O8: 0
A9: TC_PF_004 | B9: Add | C9: 0.012 | D9: 0 | E9: Hard | F9: 0 | G9: 0 | H9: 0 | I9: 0 | J9: 0 | K9: 0.0038 | L9: 0.0387 | M9: 0 | N9: 0 | O9: 0
A10: TC_PF_005 | B10: Add | C10: 0.012 | D10: 0 | E10: Hard | F10: 0 | G10: 0 | H10: 0 | I10: 0 | J10: 0 | K10: 0.0038 | L10: 0.0387 | M10: 0 | N10: 0 | O10: 0
A11: TC_PF_006 | B11: Add | C11: 0.012 | D11: 0 | E11: Hard | F11: 0 | G11: 0 | H11: 0 | I11: 0 | J11: 0 | K11: 0.0038 | L11: 0.0387 | M11: 0 | N11: 0 | O11: 0
A12: TC_PF_007 | B12: Add | C12: 0.012 | D12: 0 | E12: Hard | F12: 0 | G12: 0 | H12: 0 | I12: 0 | J12: 0 | K12: 0.0038 | L12: 0.0387 | M12: 0 | N12: 0 | O12: 0
A13: TC_PF_008 | B13: Add | C13: 0.012 | D13: 0 | E13: Hard | F13: 0 | G13: 0 | H13: 0 | I13: 0 | J13: 0 | K13: 0.0038 | L13: 0.0387 | M13: 0 | N13: 0 | O13: 0
A14: TC_PF_009 | B14: Add | C14: 0.12 | D14: 0 | E14: Hard | F14: 0 | G14: 0 | H14: 0 | I14: 0 | J14: 0 | K14: 0.05 | L14: 0.0387 | M14: 0 | N14: 0 | O14: 0
A15: TC_PF_010 | B15: Add | C15: 0.012 | D15: 0 | E15: Hard | F15: 0 | G15: 0 | H15: 0 | I15: 0 | J15: 0 | K15: 0.0038 | L15: 0.05 | M15: 0 | N15: 0 | O15: 0
A16: TC_PF_011 | B16: Add | C16: 0.012 | D16: 0 | E16: Hard | F16: 0.08 | G16: 0 | H16: 0 | I16: 0 | J16: 0 | K16: 0.0038 | L16: 0.05 | M16: 0 | N16: 0 | O16: 0
A17: TC_PF_012 | B17: Add | C17: 0.012 | D17: 0 | E17: Soft | F17: 0.08 | G17: 0 | H17: 0 | I17: 0 | J17: 0 | K17: 0.0038 | L17: 0.05 | M17: 0 | N17: 0 | O17: 0
... A40: TC_PF_035 | B40: Add | C40: 0.012 | D40: 0 | E40: Hard | F40: 0 | G40: 0 | H40: 0 | I40: 0 | J40: 0 | K40: 0.0038 | L40: 0.0387 | M40: 0 | N40: 0 | O40: 0

Sheet 07_Bound_Portfolio
A1: SCREEN 7 — BOUND PORTFOLIO
A2: ► Test Control | C2: ► Bound Portfolio Info
A3: Test Case ID | B3: Action | C3: Portfolio ID | D3: Name | E3: Vendor | F3: Currency Code | G3: Run Off | H3: Include Expired | I3: Notional AUM | J3: Deployed AUM | K3: Version | L3: As Of Date | M3: Report Date | N3: Remark
A4: [Auto-generated] | B4: [Add / Edit / Delete] | C4: [PortfolioID] | D4: [Name] | E4: [Vendor] | F4: [CurrencyCode] | G4: [RunOff] | H4: [IncludeExpired] | I4: [NotionalAUM] | J4: [DeployedAUM] | K4: [Version] | L4: [AsOfDate] | M4: [ReportDate] | N4: [Remarks]
A5: ★ Required | B5: ★ Required | C5: ★ Required | D5: ★ Required | E5: ★ Required | F5: ★ Required | G5: Optional | H5: Optional | I5: Optional | J5: Optional | K5: Optional | L5: Optional | M5: Optional | N5: Optional
A6: TC_PF_001 | B6: Add | C6: 1 | D6: Test_Portfolio_001 | E6: AIR | F6: USD | G6: 0 | H6: 1 | I6: 3000000 | J6: 2500000 | K6: v12.0 | L6: 46226
A7: TC_PF_002 | B7: Add | C7: 1 | D7: Test_Portfolio_001 | E7: AIR | F7: USD | G7: 0 | H7: 1 | I7: 3000000 | J7: 2500000 | K7: v12.0 | L7: 46202
A8: TC_PF_003 | B8: Add | C8: 1 | D8: Test_Portfolio_001 | E8: AIR | F8: USD | G8: 0 | H8: 1 | I8: 3000000 | J8: 2500000 | K8: v12.0 | L8: 46225
A9: TC_PF_004 | B9: Add | C9: 1 | D9: Test_Portfolio_002 | E9: AIR | F9: USD | G9: 0 | H9: 1 | I9: 2000000 | J9: 1750000 | K9: v12.0 | L9: 46225
A10: TC_PF_005 | B10: Add | C10: 1 | D10: Test_Portfolio_003 | E10: AIR | F10: USD | G10: 0 | H10: 1 | I10: 3000000 | J10: 2500000 | K10: v12.0 | L10: 46225
A11: TC_PF_006 | B11: Add | C11: 1 | D11: Test_Portfolio_004 | E11: AIR | F11: USD | G11: 0 | H11: 1 | I11: 3000000 | J11: 2500000 | K11: v12.0 | L11: 46225
A12: TC_PF_007 | B12: Add | C12: 1 | D12: Test_Portfolio_001 | E12: AIR | F12: USD | G12: 0 | H12: 1 | I12: 3000000 | J12: 2500000 | K12: v12.0 | L12: 46226
A13: TC_PF_008 | B13: Add | C13: 1 | D13: Test_Portfolio_002 | E13: AIR | F13: USD | G13: 0 | H13: 1 | I13: 2000000 | J13: 1750000 | K13: v12.0 | L13: 46225
A14: TC_PF_009 | B14: Add | C14: 1 | D14: Test_Portfolio_002 | E14: AIR | F14: USD | G14: 0 | H14: 1 | I14: 2000000 | J14: 1750000 | K14: v12.0 | L14: 46225
A15: TC_PF_010 | B15: Add | C15: 1 | D15: Test_Portfolio_002 | E15: AIR | F15: USD | G15: 0 | H15: 1 | I15: 2000000 | J15: 1750000 | K15: v12.0 | L15: 46225
A16: TC_PF_011 | B16: Add | C16: 1 | D16: Test_Portfolio_002 | E16: AIR | F16: USD | G16: 0 | H16: 1 | I16: 2000000 | J16: 1750000 | K16: v12.0 | L16: 46225
A17: TC_PF_012 | B17: Add | C17: 1 | D17: Test_Portfolio_002 | E17: AIR | F17: USD | G17: 0 | H17: 1 | I17: 2000000 | J17: 1750000 | K17: v12.0 | L17: 46225
... A40: TC_PF_035 | B40: Add | C40: 1 | D40: Test_Portfolio_023 | E40: AIR | F40: USD | G40: 0 | H40: 1 | I40: 2000000 | J40: 1750000 | K40: v12.0 | L40: 46225

Sheet 02_Transaction
A1: SCREEN 2 — TRANSACTION
A2: ► Test Control | D2: ► Transaction Info (Required) | L2: ► Transaction Info (Optional)
A3: Test Case ID | B3: Action | C3: Transaction ID | D3: Portfolio Name | E3: ILS Name | F3: Class | G3: Series | H3: Reset Year | I3: Transaction Type | J3: Transaction Date | K3: Quantity | L3: CUSIP | M3: Bond Price | N3: Security Instrument | O3: Broker Price | P3: Broker Name | Q3: Coupon (%) | R3: ROL | S3: Company Share | T3: Mapping Status | U3: Notes
A4: [Auto-generated] | B4: [Add / Edit / Delete] | C4: [TransactionID] | D4: [PortfolioID] | E4: [ILSName] | F4: [Class] | G4: [Series] | H4: [ResetYear] | I4: [TransactionType] | J4: [TransactionDate] | K4: [Quantity] | L4: [CUSIP] | M4: [Price] | N4: [SecurityInstrument] | O4: [BondPrice] | P4: [BrokerName] | Q4: [Coupon] | R4: [ROL] | S4: [CompanyShare] | T4: [MappingStatus] | U4: [—]
A5: ★ Required | B5: ★ Required | C5: ★ Required | D5: ★ Required | E5: ★ Required | F5: ★ Required | G5: ★ Required | H5: ★ Required | I5: ★ Required | J5: ★ Required | K5: ★ Required | L5: Optional | M5: Optional | N5: Optional | O5: Optional | P5: Optional | Q5: Optional | R5: Optional | S5: Optional | T5: Optional | U5: Optional
A6: TC_PF_001 | B6: Add | C6: TC_TR_001 | D6: Test_Portfolio_001 | E6: Nakama Re Pte. Ltd. Series 2024-1 | F6: Class 1 | G6: 2024-1 | H6: 2025 | I6: Buy | J6: 45749 | K6: 250000 | L6: 62984JAC2 | M6: 101 | N6: Cat Bond | O6: 101 | P6: BH | Q6: 0.0615072 | R6: 0.05611469 | S6: 0.0016666667 | T6: Pending | V6: =VLOOKUP(L6,[1]Sheet1!$B:$C,2,0) -> Earthquake / Japan
A7: TC_PF_001 | B7: Add | C7: TC_TR_002 | D7: Test_Portfolio_001 | E7: Montoya Re Ltd. Series 2025-1 | F7: Class B | G7: 2025-1 | H7: 2025 | I7: Buy | J7: 45751 | K7: 250000 | L7: 613752AE4 | M7: 100.2 | N7: Cat Bond | O7: 100.2 | P7: RBC | Q7: 0.1041072 | R7: 0.10300053 | S7: 0.0083333333 | T7: Pending | V7: =VLOOKUP(L7,[1]Sheet1!$B:$C,2,0) -> Earthquake / U.S., Canada, Puerto Rico, U.S. VI ; Named Storm / U.S., Puerto Rico, U.S. VI
A8: TC_PF_001 | B8: Add | C8: TC_TR_003 | D8: Test_Portfolio_001 | E8: Blue Ridge Re Ltd. Series 2023-1 | F8: Class A | G8: 2023-1 | H8: 2025 | I8: Buy | J8: 45751 | K8: 250000 | L8: 096003AA6 | M8: 102.85 | N8: Cat Bond | O8: 102.85 | P8: BH | Q8: 0.091 | R8: 0.07670283 | S8: 0.00125 | T8: Pending | V8: =VLOOKUP(L8,[1]Sheet1!$B:$C,2,0) -> Named Storm / North Carolina
A9: TC_PF_001 | B9: Add | C9: TC_TR_004 | D9: Test_Portfolio_001 | E9: Tomoni Re Pte. Ltd. Series 2022-1 | F9: Class B-1 | G9: 2022-1 | H9: 2025 | I9: Buy | J9: 45751 | K9: 250000 | L9: 89009PAB4 | M9: 101 | N9: Cat Bond | O9: 101 | P9: BH | Q9: 0.067 | R9: 0.0596383 | S9: 0.0020833333 | T9: Pending | V9: =VLOOKUP(L9,[1]Sheet1!$B:$C,2,0) -> Typhoon ; Flood / Japan
A10: TC_PF_001 | B10: Add | C10: TC_TR_005 | D10: Test_Portfolio_001 | E10: Ursa Re Ltd. Series 2023-3 | F10: Class AA | G10: 2023-3 | H10: 2024 | I10: Buy | J10: 45751 | K10: 250000 | L10: 90323WAP5 | M10: 103.95 | N10: Cat Bond | O10: 103.95 | P10: RBC | Q10: 0.0936 | R10: 0.0712207 | S10: 0.00083333333 | T10: Pending | V10: =VLOOKUP(L10,[1]Sheet1!$B:$C,2,0) -> Earthquake / California
A11: TC_PF_001 | B11: Add | C11: TC_TR_006 | D11: Test_Portfolio_001 | E11: Veraison Re Ltd. Series 2025-1 | F11: Class A | G11: 2025-1 | I11: Buy | J11: 45755 | K11: 250000 | L11: 92335TAD1 | M11: 100.25 | N11: Cat Bond | O11: 100.25 | P11: BH | Q11: 0.07378454 | R11: 0.07558766 | S11: 0.00083333333 | T11: Pending | V11: =VLOOKUP(L11,[1]Sheet1!$B:$C,2,0) -> Earthquake / U.S.
A12: TC_PF_001 | B12: Add | C12: TC_TR_007 | D12: Test_Portfolio_001 | E12: Fuchsia 2 Series 2024-1 | F12: Class A | G12: 2024-1 | H12: 2025 | I12: Buy | J12: 45755 | K12: 250000 | L12: 541917AA8 | M12: 100.65 | N12: Cat Bond | O12: 100.65 | P12: RBC | Q12: 0.0899 | R12: 0.09042534 | S12: 0.00125 | T12: Pending | V12: =VLOOKUP(L12,[1]Sheet1!$B:$C,2,0) -> Earthquake ; Named Storm / U.S., Canada, Caribbean
A13: TC_PF_001 | B13: Add | C13: TC_TR_008 | D13: Test_Portfolio_001 | E13: Fish Pond Re Ltd. Series 2024-1 | F13: Class A | G13: 2024-1 | H13: 2025 | I13: Buy | J13: 45756 | K13: 250000 | L13: 33774EAA2 | M13: 102.3 | N13: Cat Bond | O13: 102.3 | P13: BH | Q13: 0.0788 | R13: 0.06796396 | S13: 0.00098039216 | T13: Pending | V13: =VLOOKUP(L13,[1]Sheet1!$B:$C,2,0) -> Named Storm / Texas
A14: TC_PF_001 | B14: Add | C14: TC_TR_009 | D14: Test_Portfolio_001 | E14: Baldwin Re Ltd. Series 2023-1 | F14: Class A | G14: 2023-1 | H14: 2025 | I14: Buy | J14: 45756 | K14: 250000 | L14: 05826BAB2 | M14: 102.2 | N14: Cat Bond | O14: 102.2 | P14: RBC | Q14: 0.0891 | R14: 0.08130379 | S14: 0.0025 | T14: Pending | V14: =VLOOKUP(L14,[1]Sheet1!$B:$C,2,0) -> All Natural Perils / Northeast U.S.
A15: TC_PF_001 | B15: Add | C15: TC_TR_010 | D15: Test_Portfolio_001 | E15: Sanders Re III Ltd. Series 2023-1 | F15: Class A | G15: 2023-1 | H15: 2025 | I15: Buy | J15: 45756 | K15: 250000 | L15: 80001QAA1 | M15: 102.6 | N15: Cat Bond | O15: 102.6 | P15: RBC | Q15: 0.0933 | R15: 0.08220443 | S15: 0.0025 | T15: Pending | V15: =VLOOKUP(L15,[1]Sheet1!$B:$C,2,0) -> All Natural Perils / U.S. (excl. FL)
A16: TC_PF_002 | B16: Add | C16: TC_TR_001 | D16: Test_Portfolio_001 | E16: Nakama Re Pte. Ltd. Series 2024-1 | F16: Class 1 | G16: 2024-1 | H16: 2025 | I16: Buy | J16: 45749 | K16: 250000 | L16: 62984JAC2 | M16: 101 | N16: Cat Bond | O16: 101 | P16: BH | Q16: 0.0615072 | R16: 0.05611469 | S16: 0.0016666667 | T16: Pending | V16: =VLOOKUP(L16,[1]Sheet1!$B:$C,2,0) -> Earthquake / Japan
A17: TC_PF_002 | B17: Add | C17: TC_TR_002 | D17: Test_Portfolio_001 | E17: Montoya Re Ltd. Series 2025-1 | F17: Class B | G17: 2025-1 | H17: 2025 | I17: Buy | J17: 45751 | K17: 250000 | L17: 613752AE4 | M17: 100.2 | N17: Cat Bond | O17: 100.2 | P17: RBC | Q17: 0.1041072 | R17: 0.10300053 | S17: 0.0083333333 | T17: Pending | V17: =VLOOKUP(L17,[1]Sheet1!$B:$C,2,0) -> Earthquake / U.S., Canada, Puerto Rico, U.S. VI ; Named Storm / U.S., Puerto Rico, U.S. VI
A18: TC_PF_002 | B18: Add | C18: TC_TR_003 | D18: Test_Portfolio_001 | E18: Blue Ridge Re Ltd. Series 2023-1 | F18: Class A | G18: 2023-1 | H18: 2025 | I18: Buy | J18: 45751 | K18: 250000 | L18: 096003AA6 | M18: 102.85 | N18: Cat Bond | O18: 102.85 | P18: BH | Q18: 0.091 | R18: 0.07670283 | S18: 0.00125 | T18: Pending | V18: =VLOOKUP(L18,[1]Sheet1!$B:$C,2,0) -> Named Storm / North Carolina
A19: TC_PF_002 | B19: Add | C19: TC_TR_004 | D19: Test_Portfolio_001 | E19: Tomoni Re Pte. Ltd. Series 2022-1 | F19: Class B-1 | G19: 2022-1 | H19: 2025 | I19: Buy | J19: 45751 | K19: 250000 | L19: 89009PAB4 | M19: 101 | N19: Cat Bond | O19: 101 | P19: BH | Q19: 0.067 | R19: 0.0596383 | S19: 0.0020833333 | T19: Pending | V19: =VLOOKUP(L19,[1]Sheet1!$B:$C,2,0) -> Typhoon ; Flood / Japan
A20: TC_PF_002 | B20: Add | C20: TC_TR_005 | D20: Test_Portfolio_001 | E20: Ursa Re Ltd. Series 2023-3 | F20: Class AA | G20: 2023-3 | H20: 2024 | I20: Buy | J20: 45751 | K20: 250000 | L20: 90323WAP5 | M20: 103.95 | N20: Cat Bond | O20: 103.95 | P20: RBC | Q20: 0.0936 | R20: 0.0712207 | S20: 0.00083333333 | T20: Pending | V20: =VLOOKUP(L20,[1]Sheet1!$B:$C,2,0) -> Earthquake / California
A21: TC_PF_002 | B21: Add | C21: TC_TR_006 | D21: Test_Portfolio_001 | E21: Veraison Re Ltd. Series 2025-1 | F21: Class A | G21: 2025-1 | I21: Buy | J21: 45755 | K21: 250000 | L21: 92335TAD1 | M21: 100.25 | N21: Cat Bond | O21: 100.25 | P21: BH | Q21: 0.07378454 | R21: 0.07558766 | S21: 0.00083333333 | T21: Pending | V21: =VLOOKUP(L21,[1]Sheet1!$B:$C,2,0) -> Earthquake / U.S.
A22: TC_PF_002 | B22: Add | C22: TC_TR_007 | D22: Test_Portfolio_001 | E22: Fuchsia 2 Series 2024-1 | F22: Class A | G22: 2024-1 | H22: 2025 | I22: Buy | J22: 45755 | K22: 250000 | L22: 541917AA8 | M22: 100.65 | N22: Cat Bond | O22: 100.65 | P22: RBC | Q22: 0.0899 | R22: 0.09042534 | S22: 0.00125 | T22: Pending | V22: =VLOOKUP(L22,[1]Sheet1!$B:$C,2,0) -> Earthquake ; Named Storm / U.S., Canada, Caribbean
A23: TC_PF_002 | B23: Add | C23: TC_TR_008 | D23: Test_Portfolio_001 | E23: Fish Pond Re Ltd. Series 2024-1 | F23: Class A | G23: 2024-1 | H23: 2025 | I23: Buy | J23: 45756 | K23: 250000 | L23: 33774EAA2 | M23: 102.3 | N23: Cat Bond | O23: 102.3 | P23: BH | Q23: 0.0788 | R23: 0.06796396 | S23: 0.00098039216 | T23: Pending | V23: =VLOOKUP(L23,[1]Sheet1!$B:$C,2,0) -> Named Storm / Texas
A24: TC_PF_002 | B24: Add | C24: TC_TR_009 | D24: Test_Portfolio_001 | E24: Baldwin Re Ltd. Series 2023-1 | F24: Class A | G24: 2023-1 | H24: 2025 | I24: Buy | J24: 45756 | K24: 250000 | L24: 05826BAB2 | M24: 102.2 | N24: Cat Bond | O24: 102.2 | P24: RBC | Q24: 0.0891 | R24: 0.08130379 | S24: 0.0025 | T24: Pending | V24: =VLOOKUP(L24,[1]Sheet1!$B:$C,2,0) -> All Natural Perils / Northeast U.S.
A25: TC_PF_002 | B25: Add | C25: TC_TR_010 | D25: Test_Portfolio_001 | E25: Sanders Re III Ltd. Series 2023-1 | F25: Class A | G25: 2023-1 | H25: 2025 | I25: Buy | J25: 45756 | K25: 250000 | L25: 80001QAA1 | M25: 102.6 | N25: Cat Bond | O25: 102.6 | P25: RBC | Q25: 0.0933 | R25: 0.08220443 | S25: 0.0025 | T25: Pending | V25: =VLOOKUP(L25,[1]Sheet1!$B:$C,2,0) -> All Natural Perils / U.S. (excl. FL)
A26: TC_PF_003 | B26: Add | C26: TC_TR_001 | D26: Test_Portfolio_001 | E26: Nakama Re Pte. Ltd. Series 2024-1 | F26: Class 1 | G26: 2024-1 | H26: 2025 | I26: Buy | J26: 45749 | K26: 250000 | L26: 62984JAC2 | M26: 101 | N26: Cat Bond | O26: 101 | P26: BH | Q26: 0.0615072 | R26: 0.05611469 | S26: 0.0016666667 | T26: Pending | V26: =VLOOKUP(L26,[1]Sheet1!$B:$C,2,0) -> Earthquake / Japan
A27: TC_PF_003 | B27: Add | C27: TC_TR_002 | D27: Test_Portfolio_001 | E27: Montoya Re Ltd. Series 2025-1 | F27: Class B | G27: 2025-1 | H27: 2025 | I27: Buy | J27: 45751 | K27: 250000 | L27: 613752AE4 | M27: 100.2 | N27: Cat Bond | O27: 100.2 | P27: RBC | Q27: 0.1041072 | R27: 0.10300053 | S27: 0.0083333333 | T27: Pending | V27: =VLOOKUP(L27,[1]Sheet1!$B:$C,2,0) -> Earthquake / U.S., Canada, Puerto Rico, U.S. VI ; Named Storm / U.S., Puerto Rico, U.S. VI
A28: TC_PF_003 | B28: Add | C28: TC_TR_003 | D28: Test_Portfolio_001 | E28: Blue Ridge Re Ltd. Series 2023-1 | F28: Class A | G28: 2023-1 | H28: 2025 | I28: Buy | J28: 45751 | K28: 250000 | L28: 096003AA6 | M28: 102.85 | N28: Cat Bond | O28: 102.85 | P28: BH | Q28: 0.091 | R28: 0.07670283 | S28: 0.00125 | T28: Pending | V28: =VLOOKUP(L28,[1]Sheet1!$B:$C,2,0) -> Named Storm / North Carolina
A29: TC_PF_003 | B29: Add | C29: TC_TR_004 | D29: Test_Portfolio_001 | E29: Tomoni Re Pte. Ltd. Series 2022-1 | F29: Class B-1 | G29: 2022-1 | H29: 2025 | I29: Buy | J29: 45751 | K29: 250000 | L29: 89009PAB4 | M29: 101 | N29: Cat Bond | O29: 101 | P29: BH | Q29: 0.067 | R29: 0.0596383 | S29: 0.0020833333 | T29: Pending | V29: =VLOOKUP(L29,[1]Sheet1!$B:$C,2,0) -> Typhoon ; Flood / Japan
A30: TC_PF_003 | B30: Add | C30: TC_TR_005 | D30: Test_Portfolio_001 | E30: Ursa Re Ltd. Series 2023-3 | F30: Class AA | G30: 2023-3 | H30: 2024 | I30: Buy | J30: 45751 | K30: 250000 | L30: 90323WAP5 | M30: 103.95 | N30: Cat Bond | O30: 103.95 | P30: RBC | Q30: 0.0936 | R30: 0.0712207 | S30: 0.00083333333 | T30: Pending | V30: =VLOOKUP(L30,[1]Sheet1!$B:$C,2,0) -> Earthquake / California
A31: TC_PF_003 | B31: Add | C31: TC_TR_006 | D31: Test_Portfolio_001 | E31: Veraison Re Ltd. Series 2025-1 | F31: Class A | G31: 2025-1 | I31: Buy | J31: 45755 | K31: 250000 | L31: 92335TAD1 | M31: 100.25 | N31: Cat Bond | O31: 100.25 | P31: BH | Q31: 0.07378454 | R31: 0.07558766 | S31: 0.00083333333 | T31: Pending | V31: =VLOOKUP(L31,[1]Sheet1!$B:$C,2,0) -> Earthquake / U.S.
A32: TC_PF_003 | B32: Add | C32: TC_TR_007 | D32: Test_Portfolio_001 | E32: Fuchsia 2 Series 2024-1 | F32: Class A | G32: 2024-1 | H32: 2025 | I32: Buy | J32: 45755 | K32: 250000 | L32: 541917AA8 | M32: 100.65 | N32: Cat Bond | O32: 100.65 | P32: RBC | Q32: 0.0899 | R32: 0.09042534 | S32: 0.00125 | T32: Pending | V32: =VLOOKUP(L32,[1]Sheet1!$B:$C,2,0) -> Earthquake ; Named Storm / U.S., Canada, Caribbean
A33: TC_PF_003 | B33: Add | C33: TC_TR_008 | D33: Test_Portfolio_001 | E33: Fish Pond Re Ltd. Series 2024-1 | F33: Class A | G33: 2024-1 | H33: 2025 | I33: Buy | J33: 45756 | K33: 250000 | L33: 33774EAA2 | M33: 102.3 | N33: Cat Bond | O33: 102.3 | P33: BH | Q33: 0.0788 | R33: 0.06796396 | S33: 0.00098039216 | T33: Pending | V33: =VLOOKUP(L33,[1]Sheet1!$B:$C,2,0) -> Named Storm / Texas
A34: TC_PF_003 | B34: Add | C34: TC_TR_009 | D34: Test_Portfolio_001 | E34: Baldwin Re Ltd. Series 2023-1 | F34: Class A | G34: 2023-1 | H34: 2025 | I34: Buy | J34: 45756 | K34: 250000 | L34: 05826BAB2 | M34: 102.2 | N34: Cat Bond | O34: 102.2 | P34: RBC | Q34: 0.0891 | R34: 0.08130379 | S34: 0.0025 | T34: Pending | V34: =VLOOKUP(L34,[1]Sheet1!$B:$C,2,0) -> All Natural Perils / Northeast U.S.
A35: TC_PF_003 | B35: Add | C35: TC_TR_010 | D35: Test_Portfolio_001 | E35: Sanders Re III Ltd. Series 2023-1 | F35: Class A | G35: 2023-1 | H35: 2025 | I35: Buy | J35: 45756 | K35: 250000 | L35: 80001QAA1 | M35: 102.6 | N35: Cat Bond | O35: 102.6 | P35: RBC | Q35: 0.0933 | R35: 0.08220443 | S35: 0.0025 | T35: Pending | V35: =VLOOKUP(L35,[1]Sheet1!$B:$C,2,0) -> All Natural Perils / U.S. (excl. FL)
A36: TC_PF_004 | B36: Add | C36: TC_TR_021 | D36: Test_Portfolio_002 | E36: Torrey Pines Re Ltd. Series 2023-1 | F36: Class A | G36: 2023-1 | H36: 2025 | I36: Buy | J36: 46515 | K36: 250000 | L36: 89141WAF9 | M36: 101.95 | N36: Cat Bond | O36: 101.95 | P36: Swiss Re | Q36: 0.093081217 | R36: 0.06626199 | S36: 0.0016666667 | T36: Pending | V36: =VLOOKUP(L36,[1]Sheet1!$B:$C,2,0) -> Earthquake / California
A37: TC_PF_004 | B37: Add | C37: TC_TR_022 | D37: Test_Portfolio_002 | E37: Logistics Re Ltd. Series 2024-1 | F37: Class A | G37: 2024-1 | I37: Buy | J37: 46527 | K37: 250000 | L37: 54143LAB4 | M37: 101.85 | N37: Cat Bond | O37: 101.85 | P37: Swiss Re | Q37: 0.10002122 | R37: 0.09100953 | S37: 0.0026315789 | T37: Pending | V37: =VLOOKUP(L37,[1]Sheet1!$B:$C,2,0) -> Earthquake / U.S. (excl. AK, HI)
A38: TC_PF_004 | B38: Add | C38: TC_TR_023 | D38: Test_Portfolio_002 | E38: Veraison Re Ltd. Series 2023-1 | F38: Class B | G38: 2023-1 | H38: 2025 | I38: Buy | J38: 46223 | K38: 250000 | L38: 92335TAB5 | M38: 102.87 | N38: Cat Bond | O38: 102.87 | P38: Swiss Re | Q38: 0.1648 | R38: 0.1148 | S38: 0.0033333333 | T38: Pending | V38: =VLOOKUP(L38,[1]Sheet1!$B:$C,2,0) -> NULL
A39: TC_PF_004 | B39: Add | C39: TC_TR_026 | D39: Test_Portfolio_002 | E39: Ursa Re II Ltd. Series 2025-1 | F39: Class G | G39: 2025-1 | I39: Buy | J39: 46223 | K39: 250000 | L39: 91734PAH9 | M39: 102.03 | N39: Cat Bond | O39: 102.03 | P39: Swiss Re | Q39: 0.1285 | R39: 0.0785 | S39: 0.000625 | T39: Pending | V39: =VLOOKUP(L39,[1]Sheet1!$B:$C,2,0) -> Earthquake / California
A40: TC_PF_004 | B40: Add | C40: TC_TR_031 | D40: Test_Portfolio_002 | E40: Ursa Re Ltd. Series 2025-1 | F40: Class F | G40: 2025-1 | I40: Buy | J40: 46223 | K40: 250000 | L40: 90323WAR1 | M40: 101.69 | N40: Cat Bond | O40: 101.69 | P40: Swiss Re | Q40: 0.11366956 | R40: 0.06366956 | S40: 0.000625 | T40: Pending | V40: =VLOOKUP(L40,[1]Sheet1!$B:$C,2,0) -> Earthquake / California
...

Sheet 03_Mapping
A1: SCREEN 3 — TRANSACTION → ILS DEAL MAPPING | Test Cases
A2: ► Test Control | C2: ► Mapping Info | F2: ► Test Result
A3: Test Case ID | B3: Action | C3: Transaction ID | D3: ILS Deal / Name | E3: Mapping Status | F3: Expected Result | G3: Actual Result | H3: Run DateTime | I3: Notes
A4: [Auto-generated] | B4: [Add / Edit / Delete] | C4: [TransactionID] | D4: [ILSName] | E4: [MappingStatus] | F4: [Expected] | G4: [—] | H4: [—] | I4: [—]
A5: ★ Required | B5: ★ Required | C5: ★ Required | D5: ★ Required | E5: Optional | F5: ★ Required | G5: Read-only | H5: Read-only | I5: Optional
A6: TC_PF_001 | B6: ADD | C6: TC_TR_001 | D6: CB-Nakama Re Pte. Ltd. Series 2024-1 Class 1 Reset 2025
A7: TC_PF_001 | B7: ADD | C7: TC_TR_002 | D7: CB-Montoya Re Ltd. Series 2025-1 Class B Reset 2025
A8: TC_PF_001 | B8: ADD | C8: TC_TR_003 | D8: CB-Blue Ridge Re Ltd. Series 2023-1 Class A Reset 2025
A9: TC_PF_001 | B9: ADD | C9: TC_TR_004 | D9: CB-Tomoni Re Pte. Ltd. Series 2022-1 Class B-1 Reset 2025
A10: TC_PF_001 | B10: ADD | C10: TC_TR_005 | D10: CB-Ursa Re Ltd. Series 2023-3 Class AA Reset 2024
A11: TC_PF_001 | B11: ADD | C11: TC_TR_006 | D11: CB-Veraison Re Ltd. Series 2025-1 Class A
A12: TC_PF_001 | B12: ADD | C12: TC_TR_007 | D12: CB-Fuchsia 2 Series 2024-1 Class A Reset 2025
A13: TC_PF_001 | B13: ADD | C13: TC_TR_008 | D13: CB-Fish Pond Re Ltd. Series 2024-1 Class A Reset 2025
A14: TC_PF_001 | B14: ADD | C14: TC_TR_009 | D14: CB-Baldwin Re Ltd. Series 2023-1 Class A Reset 2025
A15: TC_PF_001 | B15: ADD | C15: TC_TR_010 | D15: CB-Sanders Re III Ltd. Series 2023-1 Class A Reset 2025
A16: TC_PF_002 | B16: ADD | C16: TC_TR_001 | D16: CB-Nakama Re Pte. Ltd. Series 2024-1 Class 1 Reset 2025
A17: TC_PF_002 | B17: ADD | C17: TC_TR_002 | D17: CB-Montoya Re Ltd. Series 2025-1 Class B Reset 2025
... A256: TC_PF_035 | B256: ADD | C256: TC_TR_007 | D256: CB-Fuchsia 2 Series 2024-1 Class A Reset 2025

Sheet 05_Pricing_Parameters
A1: SCREEN 5 — PORTFOLIO PRICING PARAMETERS | Test Cases
A2: ► Test Control | C2: ► Context | D2: ► Pricing Params | N2: ► Test Result
A3: Test Case ID | B3: Action | C3: Portfolio ID | D3: Vendor | E3: Target UW Return % | F3: Tail Return Contrib % | G3: Tail Return Target % | H3: Target Capacity Charge % | I3: A | J3: R % | K3: Cap | L3: Threshold % | M3: Target Return on Risk % | N3: Expected Result | O3: Actual Result | P3: Run DateTime | Q3: Notes
A4: [Auto-generated] | B4: [Save / Delete] | C4: [PortfolioID] | D4: [Vendor] | E4: [TargetUWReturn] | F4: [TailReturnContributionPerc] | G4: [TailReturnTarget] | H4: [TargetCapacityCharge] | I4: [A] | J4: [R] | K4: [Cap] | L4: [Thresh] | M4: [TargetReturnOnRisk] | N4: [Expected] | O4: [—] | P4: [—] | Q4: [—]
A5: ★ Required | B5: ★ Required | C5: ★ Required | D5: ★ Required | E5: Optional | F5: Optional | G5: Optional | H5: Optional | I5: Optional | J5: Optional | K5: Optional | L5: Optional | M5: Optional | N5: ★ Required | O5: Read-only | P5: Read-only | Q5: Optional
A6: TC_PP_001 | B6: Save | C6: 1 | D6: AIR | E6: 0.1 | F6: 0.0075 | G6: 0.075 | H6: 0.025 | I6: 4 | J6: 0.19109 | K6: 6 | L6: 0.01 | M6: 0.2 | N6: PASS | O6: PASS | P6: 2026-07-10 13:57:37 | Q6: Default values
Q14: Different vendor
A22: Legend:
A23: Required field
A24: Optional field
A25: Auto-populated
A26: PASS result
A27: FAIL result

Sheet Lookups
A1: Action | B1: TransactionType | C1: SecurityInstrument | D1: MappingStatus | E1: ConstraintType | F1: Vendor | G1: CurrencyCode | H1: RunOff | I1: IncludeExpired | J1: HurdleType | K1: Expected
A2: Add | B2: Buy | C2: CAT Bond | D2: Mapped | E2: Cedant | F2: AIR | G2: USD | H2: 0 | I2: 0 | J2: Hurdle | K2: PASS
A3: Edit | B3: Sell | C3: ILW Long | D3: Pending | E3: Single | F3: RMS | G3: EUR | H3: 1 | I3: 1 | J3: Absolute | K3: FAIL
A4: Delete | C4: ILW Short | D4: No Mapping Found | E4: Issuer | F4: KCC | G4: GBP | J4: Relative
A5: Save | C5: Reinsurance | E5: PerilRegion | F5: CoreLogic | G5: JPY
C6: Retro QS | E6: ReinsuranceType | F6: Verisk | G6: CHF
C7: Retro XOL | F7: AIR Worldwide | G7: CAD
C8: Side Car | G8: AUD
G9: SGD
G10: HKD
G11: NZD
