Workbook
Name _100__Premium: #REF!
Name _100__Premium: '[3]Bound Portfolio Report'!$AA$8:$AA$10000
Name _100__Premium: #REF!
Name _100__Premium: #REF!
Name _100__Premium: #REF!
Name _100__Premium: #REF!
Name _100__Premium: #REF!
Name _100_AEP: #REF!
Name _100_AEP: #REF!
Name _100_AEP: '[3]Bound Portfolio Report'!$BF$8:$BF$10000
Name _100_AEP: #REF!
Name _100_AEP: #REF!
Name _100_AEP: #REF!
Name _100_AEP: '[4]Bound Portfolio Report'!$BF$8:$BF$10000
Name _500_AEP: #REF!
Name _500_AEP: #REF!
Name _500_AEP: '[3]Bound Portfolio Report'!$BG$8:$BG$10000
Name _500_AEP: #REF!
Name _500_AEP: #REF!
Name _500_AEP: #REF!
Name _500_AEP: '[4]Bound Portfolio Report'!$BG$8:$BG$10000
Name _AREResultPropertyNames: '[3]~AnalyzeReAddIn'!$B$1:$B$30
Name Actual___of_AUM: #REF!
Name Actual___of_AUM: '[3]Bound Portfolio Report'!$BH$8:$BH$10000
Name Actual___of_AUM: #REF!
Name Actual___of_AUM: #REF!
Name Actual___of_AUM: #REF!
Name Actual___of_AUM: #REF!
Name Actual___of_AUM: #REF!
Name Aggregate_Limit__100: '[3]Bound Portfolio Report'!$Z$8:$Z$10000
Name Aggregate_Limit__100: #REF!
Name Aggregate_Limit__100: #REF!
Name Aggregate_Limit__100: #REF!
Name AIR_ARe_CipherID: [3]BoundLayerDB!$E$3:$E$1048576
Name AIR_ARe_CipherID: #REF!
Name AIR_ARe_CipherID: #REF!
Name AIR_ARe_LayerID: [3]BoundLayerDB!$D$3:$D$1048576
Name AIR_ARe_LayerID: #REF!
Name AIR_ARe_LayerID: #REF!
Name Avg_Rate_Change_Projection: #REF!
Name Avg_Rate_Change_Projection: #REF!
Name Avg_Rate_Change_Projection: #REF!
Name Bond_Price__Binding: #REF!
Name Bond_Price__Binding: #REF!
Name Bond_Price__Binding: #REF!
Name Bound_Date: '[3]Bound Portfolio Report'!$O$8:$O$10000
Name Bound_Date: #REF!
Name Bound_Date: #REF!
Name Bound_Date: #REF!
Name CipherID: #REF!
Name CipherID: #REF!
Name CipherID: #REF!
Name Co_TVAR_100: #REF!
Name Co_TVAR_100: #REF!
Name Co_TVAR_100: '[3]Bound Portfolio Report'!$BR$8:$BR$10000
Name Co_TVAR_100: #REF!
Name Co_TVAR_100: #REF!
Name Co_TVAR_100: #REF!
Name Co_TVAR_100: '[4]Bound Portfolio Report'!$BR$8:$BR$10000
Name Co_TVAR_1000: #REF!

Sheet Summary
A1: Report Name
A3: Portfolio Name
A4: Vendor
A5: Report Date
A6: PortfolioID
A7: ReportID
A8: Fronting
A9: SecurityInstrument
A10: AsOfDate
A11: Run Off
A12: IncludeExpired
A13: Total AUM
A14: Deployed AUM

Sheet Inputs
A1: Input Name | B1: Input Values | F1: Input Values
A2: PortfolioID | B2: 900000005 | F2: 4 | I2: 1
A3: ReportDate | B3: 46225 | F3: 44835 | I3: 786
A4: Vendor | B4: AIR | F4: PIMCOVIEW | I4: PIMCOVIEW
A5: Fronting | B5: all | F5: all | I5: all
A6: SecurityInstrument | B6: all | F6: all | I6: all
A7: AsOfDate | B7: 46225 | F7: 44835 | I7: =I3 -> 786
A8: RunOff | B8: 0 | F8: 0 | I8: 0
A9: IncludeExpired | B9: 1 | F9: 1 | I9: 0
A10: ExportID | B10: 760870 | F10: 674684 | I10: 808561
A11: AEPType | B11: AEPTVAR
A12: AEPCoTVARType | B12: AEPCOTVAR

Sheet ILS Report- Combined
B1: KRC ILS Fund | C1: =#REF! -> #REF!
B2: Portfolio Summary | C2: Deployed Capital | D2: Available Capital | H2: NAV | M2: Modeled Assumptions
B3: Market Value ($) | C3: ='P&L'!C1 -> 3750000 | D3: ='P&L'!C2 -> 4000000 | H3: Tail Risk Summary | J3: Deployed | K3: Available | N3: Return Ratios | O3: Deployed % NAV | P3: Available % NAV
B4: Gross Notional ($) | C4: ='P&L'!B38 -> 5250000 | D4: ='P&L'!B38 -> 5250000 | I4: USD | J4: % NAV | K4: % NAV | M4: Expected_Return Excess | N4: =VLOOKUP(M4,'P&L'!$A$25:$C$47,2,0) -> 610841 | O4: =N4/$C$3 -> 0.16289093 | P4: =N4/$D$3 -> 0.15271025
H5: Total - All Perils | I5: ='Region Peril'!AE28 -> 0 | J5: =I5/$C$3 -> 0 | K5: =I5/$D$3 -> 0 | M5: Expected_Return Net | N5: =VLOOKUP(M5,'P&L'!$A$25:$C$47,2,0) -> 557316 | O5: =N5/$C$3 -> 0.1486176 | P5: =N5/$D$3 -> 0.139329
H6: Top 5 Peril regions | M6: Standard Deviation | N6: =VLOOKUP(M6,'P&L'!$A$25:$C$47,2,0) -> 436656 | O6: =N6/$C$3 -> 0.1164416 | P6: =N6/$D$3 -> 0.109164
B7: Gross Written Premium | C7: ='P&L'!B5/'ILS Report- Combined'!C3 -> 0.20145253 | D7: ='P&L'!B5/'ILS Report- Combined'!D3 -> 0.18886175 | H7: =INDEX('Region Peril'!$X$5:$X$9,MATCH(I7,'Region Peril'!$AE$5:$AE$9,0)) -> #NUM! | I7: =SMALL('Region Peril'!$AE$5:$AE$9,1) -> #NUM! | J7: =I7/$C$3 -> #NUM! | K7: =I7/$D$3 -> #NUM! | M7: Sharpe Ratio | N7: =VLOOKUP(M7,'P&L'!$A$25:$C$47,2,0) -> 1.2763274
H8: =INDEX('Region Peril'!$X$5:$X$9,MATCH(I8,'Region Peril'!$AE$5:$AE$9,0)) -> #NUM! | I8: =SMALL('Region Peril'!$AE$5:$AE$9,2) -> #NUM! | J8: =I8/$C$3 -> #NUM! | K8: =I8/$D$3 -> #NUM! | M8: CV | N8: =VLOOKUP(M8,'P&L'!$A$25:$C$47,2,0) -> 0.78349805
B9: Gross Expected Loss | C9: =-'P&L'!$B$9/C3 -> -0.0385616 | D9: =-'P&L'!$B$9/D3 -> -0.0361515 | H9: =INDEX('Region Peril'!$X$5:$X$9,MATCH(I9,'Region Peril'!$AE$5:$AE$9,0)) -> #NUM! | I9: =SMALL('Region Peril'!$AE$5:$AE$9,3) -> #NUM! | J9: =I9/$C$3 -> #NUM! | K9: =I9/$D$3 -> #NUM! | M9: Best Reasonable Outcome | N9: =VLOOKUP(M9,'P&L'!$A$23:$C$40,2,0) -> 701922 | O9: =N9/$C$3 -> 0.1871792 | P9: =N9/$D$3 -> 0.1754805
B10: Expense | C10: =-('P&L'!$B$7+'P&L'!$B$10+'P&L'!$B$11+'P&L'!$B$12+'P&L'!$B$16+'P&L'!$B$17+'P&L'!$B$18)/C3 -> -0.016853333 | D10: =-('P&L'!$B$7+'P&L'!$B$10+'P&L'!$B$11+'P&L'!$B$12+'P&L'!$B$16+'P&L'!$B$17+'P&L'!$B$18)/D3 -> -0.0158 | H10: =INDEX('Region Peril'!$X$5:$X$9,MATCH(I10,'Region Peril'!$AE$5:$AE$9,0)) -> #NUM! | I10: =SMALL('Region Peril'!$AE$5:$AE$9,4) -> #NUM! | J10: =I10/$C$3 -> #NUM! | K10: =I10/$D$3 -> #NUM! | M10: Omega Ratio | N10: =ABS(SUMIF('EP Curve'!F1:F10002,">0")/SUMIF('EP Curve'!F1:F10002,"<0")) -> 12.266849
B11: Investment Income | C11: ='P&L'!$B$15/'ILS Report- Combined'!C3 -> 0.00258 | D11: ='P&L'!$B$15/'ILS Report- Combined'!D3 -> 0.00241875 | H11: =INDEX('Region Peril'!$X$5:$X$9,MATCH(I11,'Region Peril'!$AE$5:$AE$9,0)) -> #NUM! | I11: =SMALL('Region Peril'!$AE$5:$AE$9,5) -> #NUM! | J11: =I11/$C$3 -> #NUM! | K11: =I11/$D$3 -> #NUM! | M11: ProbabilityofLoss | N11: =VLOOKUP(M11,'P&L'!$A$25:$C$47,2,0) -> 0.0715
H12: Liquidity Provisions | J12: 0.025 | K12: 0.025 | M12: 1 in 100 yr PML | N12: =VLOOKUP(M12,'P&L'!$A$25:$C$47,2,0) -> -1785420.8 | O12: =N12/$C$3 -> -0.4761122 | P12: =N12/$D$3 -> -0.44635519
B13: Gross Total Return | C13: =SUM(C7:C11) -> 0.1486176 | D13: =SUM(D7:D11) -> 0.139329 | I13: USD | J13: % NAV | K13: % NAV | M13: 1 in 250 yr PML | N13: =VLOOKUP(M13,'P&L'!$A$25:$C$47,2,0) -> -2007508.3 | O13: =N13/$C$3 -> -0.53533555 | P13: =N13/$D$3 -> -0.50187708
M14: 1% TVaR | N14: =VLOOKUP(M14,'P&L'!$A$25:$C$47,2,0) -> -2035586.4
B15: Number of Positions | C15: =BoundPositions!$C$2 -> 0 | M15: RAROC (99%) | N15: =VLOOKUP(M15,'P&L'!$A$25:$C$47,2,0) -> 0.31214827
M16: Notional Occurrence Limits (Short) | N16: =VLOOKUP(M16,'P&L'!$A$25:$C$47,2,0) -> 5250000
M17: =3&":"&3 -> 3:3 | N17: =5&":"&5 -> 5:5 | O17: =8&":"&8 -> 8:8 | P17: =7&":"&7 -> 7:7
B18: Exposure Summary | D18: ='P&L'!B8 -> 755447 | M18: Scenario Analysis
B19: Peril | C19: Region | D19: Expected Loss (% of total AAL) | E19: TVAR Allocation (% of Deployed Capital) | F19: CoTVAR Allocation (% of WWAP) | M19: Description | N19: Industry Loss($B) | O19: P&L | P19: P&L(Event)
B20: US Hurricane | C20: Florida Hurricane | D20: =VLOOKUP($C20,'Region Peril'!$B$4:$C$80,2,FALSE)/'P&L'!$B$9 -> 0.12822723 | E20: =VLOOKUP($C20,'Region Peril'!$B$4:$F$80,5,FALSE)/$C$3 -> 0.25062758 | F20: =VLOOKUP($C20,'Region Peril'!$B$4:$G$80,6,FALSE)/'Region Peril'!$G$5 -> 0.070743483 | M20: =INDEX(HistoricalEvents!$D$4:$D$953,MATCH(O20,HistoricalEvents!$G$4:$G$953,0)) -> 0 | N20: =(INDEX(HistoricalEvents!$E$4:$E$13,MATCH(O20,HistoricalEvents!$H$4:$H$13,0)))/1000000000 -> #N/A | O20: =SMALL(HistoricalEvents!$D$4:$G$13,1) -> 1 | P20: =SMALL(HistoricalEvents!$D$4:$G$13,1) -> 1
C21: Northeast Hurricane | D21: =VLOOKUP($C21,'Region Peril'!$B$4:$C$80,2,FALSE)/'P&L'!$B$9 -> 0.099249378 | E21: =VLOOKUP($C21,'Region Peril'!$B$4:$F$80,5,FALSE)/$C$3 -> 0.311902 | F21: =VLOOKUP($C21,'Region Peril'!$B$4:$G$80,6,FALSE)/'Region Peril'!$G$5 -> 0.016072806 | M21: =INDEX(HistoricalEvents!$D$4:$D$953,MATCH(O21,HistoricalEvents!$G$4:$G$953,0)) -> 0 | N21: =(INDEX(HistoricalEvents!$E$4:$E$13,MATCH(O21,HistoricalEvents!$H$4:$H$13,0)))/1000000000 -> #N/A | O21: =SMALL(HistoricalEvents!$D$4:$G$13,2) -> 3 | P21: =SMALL(HistoricalEvents!$D$4:$G$13,2) -> 3
C22: Texas Hurricane | D22: =VLOOKUP($C22,'Region Peril'!$B$4:$C$80,2,FALSE)/'P&L'!$B$9 -> 0.1305802 | E22: =VLOOKUP($C22,'Region Peril'!$B$4:$F$80,5,FALSE)/$C$3 -> 0.2701928 | F22: =VLOOKUP($C22,'Region Peril'!$B$4:$G$80,6,FALSE)/'Region Peril'!$G$5 -> 0.01493253 | M22: =INDEX(HistoricalEvents!$D$4:$D$953,MATCH(O22,HistoricalEvents!$G$4:$G$953,0)) -> 0 | N22: =(INDEX(HistoricalEvents!$E$4:$E$13,MATCH(O22,HistoricalEvents!$H$4:$H$13,0)))/1000000000 -> #N/A | O22: =SMALL(HistoricalEvents!$D$4:$G$13,3) -> 5 | P22: =SMALL(HistoricalEvents!$D$4:$G$13,3) -> 5
C23: Louisiana Hurricane | D23: =VLOOKUP($C23,'Region Peril'!$B$4:$C$80,2,FALSE)/'P&L'!$B$9 -> 0.33989417 | E23: =VLOOKUP($C23,'Region Peril'!$B$4:$F$80,5,FALSE)/$C$3 -> 0.66365616 | F23: =VLOOKUP($C23,'Region Peril'!$B$4:$G$80,6,FALSE)/'Region Peril'!$G$5 -> 0.77208582 | M23: =INDEX(HistoricalEvents!$D$4:$D$953,MATCH(O23,HistoricalEvents!$G$4:$G$953,0)) -> 0 | N23: =(INDEX(HistoricalEvents!$E$4:$E$13,MATCH(O23,HistoricalEvents!$H$4:$H$13,0)))/1000000000 -> #N/A | O23: =SMALL(HistoricalEvents!$D$4:$G$13,4) -> 6 | P23: =SMALL(HistoricalEvents!$D$4:$G$13,4) -> 6
C24: Southeast Hurricane | D24: =VLOOKUP($C24,'Region Peril'!$B$4:$C$80,2,FALSE)/'P&L'!$B$9 -> 0.13440718 | E24: =VLOOKUP($C24,'Region Peril'!$B$4:$F$80,5,FALSE)/$C$3 -> 0.32743279 | F24: =VLOOKUP($C24,'Region Peril'!$B$4:$G$80,6,FALSE)/'Region Peril'!$G$5 -> 0.032701037 | M24: =INDEX(HistoricalEvents!$D$4:$D$953,MATCH(O24,HistoricalEvents!$G$4:$G$953,0)) -> 5.1288171e+08 | N24: =(INDEX(HistoricalEvents!$E$4:$E$13,MATCH(O24,HistoricalEvents!$H$4:$H$13,0)))/1000000000 -> #N/A | O24: =SMALL(HistoricalEvents!$D$4:$G$13,5) -> 9 | P24: =SMALL(HistoricalEvents!$D$4:$G$13,5) -> 9
C25: Gulf of Mexico WS | D25: =VLOOKUP($C25,'Region Peril'!$B$4:$C$80,2,FALSE)/'P&L'!$B$9 -> 0.37843743 | E25: =VLOOKUP($C25,'Region Peril'!$B$4:$F$80,5,FALSE)/$C$3 -> 0.66690766 | F25: =VLOOKUP($C25,'Region Peril'!$B$4:$G$80,6,FALSE)/'Region Peril'!$G$5 -> 0.82440829 | M25: =INDEX(HistoricalEvents!$D$4:$D$953,MATCH(O25,HistoricalEvents!$G$4:$G$953,0)) -> 8.9098664e+08 | N25: =(INDEX(HistoricalEvents!$E$4:$E$13,MATCH(O25,HistoricalEvents!$H$4:$H$13,0)))/1000000000 -> #N/A | O25: =SMALL(HistoricalEvents!$D$4:$G$13,6) -> 11 | P25: =SMALL(HistoricalEvents!$D$4:$G$13,6) -> 11
B26: Earthquake | C26: California Earthquake | D26: =VLOOKUP($C26,'Region Peril'!$B$4:$C$80,2,FALSE)/'P&L'!$B$9 -> 0.002027789 | E26: =VLOOKUP($C26,'Region Peril'!$B$4:$F$80,5,FALSE)/$C$3 -> 0.007819479 | F26: =VLOOKUP($C26,'Region Peril'!$B$4:$G$80,6,FALSE)/'Region Peril'!$G$5 -> 0.00091323884 | M26: =INDEX(HistoricalEvents!$D$4:$D$953,MATCH(O26,HistoricalEvents!$G$4:$G$953,0)) -> 3.570069e+08 | N26: =(INDEX(HistoricalEvents!$E$4:$E$13,MATCH(O26,HistoricalEvents!$H$4:$H$13,0)))/1000000000 -> #N/A | O26: =SMALL(HistoricalEvents!$D$4:$G$13,7) -> 17 | P26: =SMALL(HistoricalEvents!$D$4:$G$13,7) -> 17
C27: US Earthquake xCA | D27: =VLOOKUP($C27,'Region Peril'!$B$4:$C$80,2,FALSE)/'P&L'!$B$9 -> #N/A | E27: =VLOOKUP($C27,'Region Peril'!$B$4:$F$80,5,FALSE)/$C$3 -> #N/A | F27: =VLOOKUP($C27,'Region Peril'!$B$4:$G$80,6,FALSE)/'Region Peril'!$G$5 -> #N/A | M27: =INDEX(HistoricalEvents!$D$4:$D$953,MATCH(O27,HistoricalEvents!$G$4:$G$953,0)) -> 3.570069e+08 | N27: =(INDEX(HistoricalEvents!$E$4:$E$13,MATCH(O27,HistoricalEvents!$H$4:$H$13,0)))/1000000000 -> #N/A | O27: =SMALL(HistoricalEvents!$D$4:$G$13,8) -> 17 | P27: =SMALL(HistoricalEvents!$D$4:$G$13,8) -> 17
C28: Europe Earthquake | D28: =VLOOKUP($C28,'Region Peril'!$B$4:$C$80,2,FALSE)/'P&L'!$B$9 -> 0 | E28: =VLOOKUP($C28,'Region Peril'!$B$4:$F$80,5,FALSE)/$C$3 -> 0 | F28: =VLOOKUP($C28,'Region Peril'!$B$4:$G$80,6,FALSE)/'Region Peril'!$G$5 -> 0 | M28: =INDEX(HistoricalEvents!$D$4:$D$953,MATCH(O28,HistoricalEvents!$G$4:$G$953,0)) -> 1.9919565e+08 | N28: =(INDEX(HistoricalEvents!$E$4:$E$13,MATCH(O28,HistoricalEvents!$H$4:$H$13,0)))/1000000000 -> #N/A | O28: =SMALL(HistoricalEvents!$D$4:$G$13,9) -> 52 | P28: =SMALL(HistoricalEvents!$D$4:$G$13,9) -> 52
C29: Japan Earthquake | D29: =VLOOKUP($C29,'Region Peril'!$B$4:$C$80,2,FALSE)/'P&L'!$B$9 -> 0 | E29: =VLOOKUP($C29,'Region Peril'!$B$4:$F$80,5,FALSE)/$C$3 -> 0 | F29: =VLOOKUP($C29,'Region Peril'!$B$4:$G$80,6,FALSE)/'Region Peril'!$G$5 -> 0 | M29: =INDEX(HistoricalEvents!$D$4:$D$953,MATCH(O29,HistoricalEvents!$G$4:$G$953,0)) -> 3.4529243e+08 | N29: =(INDEX(HistoricalEvents!$E$4:$E$13,MATCH(O29,HistoricalEvents!$H$4:$H$13,0)))/1000000000 -> #N/A | O29: =SMALL(HistoricalEvents!$D$4:$G$13,10) -> 66 | P29: =SMALL(HistoricalEvents!$D$4:$G$13,10) -> 66
C30: Mexico Earthquake | D30: =VLOOKUP($C30,'Region Peril'!$B$4:$C$80,2,FALSE)/'P&L'!$B$9 -> 0 | E30: =VLOOKUP($C30,'Region Peril'!$B$4:$F$80,5,FALSE)/$C$3 -> 0 | F30: =VLOOKUP($C30,'Region Peril'!$B$4:$G$80,6,FALSE)/'Region Peril'!$G$5 -> 0
C31: South America Earthquake | D31: =VLOOKUP($C31,'Region Peril'!$B$4:$C$80,2,FALSE)/'P&L'!$B$9 -> 0 | E31: =VLOOKUP($C31,'Region Peril'!$B$4:$F$80,5,FALSE)/$C$3 -> 0 | F31: =VLOOKUP($C31,'Region Peril'!$B$4:$G$80,6,FALSE)/'Region Peril'!$G$5 -> 0
B32: Typhoon/WinterStorm | C32: Japan Typhoon | D32: =VLOOKUP($C32,'Region Peril'!$B$4:$C$80,2,FALSE)/'P&L'!$B$9 -> 0 | E32: =VLOOKUP($C32,'Region Peril'!$B$4:$F$80,5,FALSE)/$C$3 -> 0 | F32: =VLOOKUP($C32,'Region Peril'!$B$4:$G$80,6,FALSE)/'Region Peril'!$G$5 -> 0
C33: Europe Tropical Cyclone | D33: =VLOOKUP($C33,'Region Peril'!$B$4:$C$80,2,FALSE)/'P&L'!$B$9 -> 0 | E33: =VLOOKUP($C33,'Region Peril'!$B$4:$F$80,5,FALSE)/$C$3 -> 0 | F33: =VLOOKUP($C33,'Region Peril'!$B$4:$G$80,6,FALSE)/'Region Peril'!$G$5 -> 0
C34: Mexico Hurricane | D34: =VLOOKUP($C34,'Region Peril'!$B$4:$C$80,2,FALSE)/'P&L'!$B$9 -> 0.00027369026 | E34: =VLOOKUP($C34,'Region Peril'!$B$4:$F$80,5,FALSE)/$C$3 -> 0.0010553934 | F34: =VLOOKUP($C34,'Region Peril'!$B$4:$G$80,6,FALSE)/'Region Peril'!$G$5 -> 0
C35: US Winter Storm | D35: =VLOOKUP($C35,'Region Peril'!$B$4:$C$80,2,FALSE)/'P&L'!$B$9 -> 0.0007444827 | E35: =VLOOKUP($C35,'Region Peril'!$B$4:$F$80,5,FALSE)/$C$3 -> 0.0028708444 | F35: =VLOOKUP($C35,'Region Peril'!$B$4:$G$80,6,FALSE)/'Region Peril'!$G$5 -> 0
B36: Severe Convective Storm | C36: US Severe Storm | D36: =VLOOKUP($C36,'Region Peril'!$B$4:$C$80,2,FALSE)/'P&L'!$B$9 -> 0.0024378531 | E36: =VLOOKUP($C36,'Region Peril'!$B$4:$F$80,5,FALSE)/$C$3 -> 0.0094007514 | F36: =VLOOKUP($C36,'Region Peril'!$B$4:$G$80,6,FALSE)/'Region Peril'!$G$5 -> 0
B37: Inland Flood | C37: US Inland Flood | D37: =VLOOKUP($C37,'Region Peril'!$B$4:$C$80,2,FALSE)/'P&L'!$B$9 -> 0 | E37: =VLOOKUP($C37,'Region Peril'!$B$4:$F$80,5,FALSE)/$C$3 -> 0 | F37: =VLOOKUP($C37,'Region Peril'!$B$4:$G$80,6,FALSE)/'Region Peril'!$G$5 -> 0
B38: Wildfire | C38: US Wildfire | D38: =VLOOKUP($C38,'Region Peril'!$B$4:$C$80,2,FALSE)/'P&L'!$B$9 -> 0 | E38: =VLOOKUP($C38,'Region Peril'!$B$4:$F$80,5,FALSE)/$C$3 -> 0 | F38: =VLOOKUP($C38,'Region Peril'!$B$4:$G$80,6,FALSE)/'Region Peril'!$G$5 -> 0
B39: Terrorism | C39: Terrorism | D39: =VLOOKUP($C39,'Region Peril'!$B$4:$C$80,2,FALSE)/'P&L'!$B$9 -> 0 | E39: =VLOOKUP($C39,'Region Peril'!$B$4:$F$80,5,FALSE)/$C$3 -> 0 | F39: =VLOOKUP($C39,'Region Peril'!$B$4:$G$80,6,FALSE)/'Region Peril'!$G$5 -> 0
B40: All other WS | C40: All other WS | D40: =VLOOKUP($C40,'Region Peril'!$B$4:$C$80,2,FALSE)/'P&L'!$B$9 -> 0.0031979669 | E40: =VLOOKUP($C40,'Region Peril'!$B$4:$F$80,5,FALSE)/$C$3 -> 0.012331872 | F40: =VLOOKUP($C40,'Region Peril'!$B$4:$G$80,6,FALSE)/'Region Peril'!$G$5 -> 0
...

Sheet P&L
A1: P&L Report | B1: Deployed AUM | C1: =VLOOKUP(B1,$A$26:$B$42,2,FALSE) -> 3750000
B2: Total AUM | C2: =VLOOKUP(B2,$A$26:$B$42,2,FALSE) -> 4000000
A3: Expected P&L | B3: Expected | C3: 0.1 | D3: 0.5 | E3: 0.8 | F3: 0.9 | G3: 0.96 | H3: 0.98 | I3: 0.99 | J3: 0.996 | K3: 0.998 | L3: 0.999
C4: 1.111 yr | D4: 2 yr | E4: 5 yr | F4: 10 yr | G4: 25 yr | H4: 50 yr | I4: 100 yr | J4: 250 yr | K4: 500 yr | L4: 1000 yr
A5: Gross Written Premium | B5: 755447 | C5: 755447 | D5: 755447 | E5: 755447 | F5: 755447 | G5: 755447 | H5: 755447 | I5: 755447 | J5: 755447 | K5: 755447 | L5: 755447
A6: Reinstatement Premium | B6: 0 | C6: 0 | D6: 0 | E6: 0 | F6: 0 | G6: 0 | H6: 0 | I6: 0 | J6: 0 | K6: 0 | L6: 0
A7: Leverage Expense | B7: 0 | C7: 0 | D7: 0 | E7: 0 | F7: 0 | G7: 0 | H7: 0 | I7: 0 | J7: 0 | K7: 0 | L7: 0
A8: Net Written Premium | B8: 755447 | C8: 755447 | D8: 755447 | E8: 755447 | F8: 755447 | G8: 755447 | H8: 755447 | I8: 755447 | J8: 755447 | K8: 755447 | L8: 755447
A9: Gross Loss Amount | B9: 144606 | C9: 0 | D9: 0 | E9: 0 | F9: 499999.55 | G9: 1202416.8 | H9: 1809700.5 | I9: 2487342.8 | J9: 2709430.3 | K9: 2791852.9 | L9: 3272442.7
A10: Acquisition Expenses | B10: 0 | C10: 0 | D10: 0 | E10: 0 | F10: 0 | G10: 0 | H10: 0 | I10: 0 | J10: 0 | K10: 0 | L10: 0
A11: Federal Excise Tax | B11: 0 | C11: 0 | D11: 0 | E11: 0 | F11: 0 | G11: 0 | H11: 0 | I11: 0 | J11: 0 | K11: 0 | L11: 0
A12: Fronting Fee | B12: 0 | C12: 0 | D12: 0 | E12: 0 | F12: 0 | G12: 0 | H12: 0 | I12: 0 | J12: 0 | K12: 0 | L12: 0
A13: Net Underwriting Income | B13: 610841 | C13: 755447 | D13: 755447 | E13: 755447 | F13: 255447.45 | G13: -446969.79 | H13: -1054253.5 | I13: -1731895.8 | J13: -1953983.3 | K13: -2036405.9 | L13: -2516995.7
A14: Excess Return Gross | B14: 0.15271025 | C14: 0.18886175 | D14: 0.18886175 | E14: 0.18886175 | F14: 0.063861862 | G14: -0.11174245 | H14: -0.26356338 | I14: -0.43297394 | J14: -0.48849583 | K14: -0.50910148 | L14: -0.62924893
A15: Investment Income | B15: 9675 | C15: 9675 | D15: 9675 | E15: 9675 | F15: 9675 | G15: 9675 | H15: 9675 | I15: 9675 | J15: 9675 | K15: 9675 | L15: 9675
A16: Op/Org Expenses | B16: 15200 | C16: 15200 | D16: 15200 | E16: 15200 | F16: 15200 | G16: 15200 | H16: 15200 | I16: 15200 | J16: 15200 | K16: 15200 | L16: 15200
... A20: Total Net Return | B20: 0.139329 | C20: 0.1754805 | D20: 0.1754805 | E20: 0.1754805 | F20: 0.050480612 | G20: -0.1251237 | H20: -0.27694463 | I20: -0.44635519 | J20: -0.50187708 | K20: -0.52248273 | L20: -0.64263018
A23: Portfolio Metrics
A25: Metric | B25: USD | C25: %NAV
A26: Expected_Return Excess | B26: 610841 | C26: 0.15271025
A27: Expected_Return Net | B27: 557316 | C27: 0.139329
A28: Standard Deviation | B28: 436656 | C28: 0.109164
A29: Sharpe Ratio | B29: 1.2763274 | C29: 1.2763274
A30: CV | B30: 0.78349805
A31: Best Reasonable Outcome | B31: 701922 | C31: 0.1754805
A32: ProbabilityOfLoss | B32: 0.0715
A33: 1 in 100 yr PML | B33: -1785420.8 | C33: -0.44635519
A34: 1 in 250 yr PML | B34: -2007508.3 | C34: -0.50187708
A35: 1% TVAR | B35: -2035586.4 | C35: -0.5088966
A36: RAROC (99%) | B36: 0.31214827
A37: Notional Occurrence Limits (Short) | B37: 5250000
A38: Notional Aggregate Limits (Short) | B38: 5250000
A39: Leverage | C39: 1.3125
A40: ROL | C40: 0.14389467
A41: Deployed AUM | B41: 3750000
A42: Total AUM | B42: 4000000
A43: Deployed AUM
A44: Total AUM

Sheet EP Curve
A3: AggLoss | B3: Rank | C3: Probability | D3: UW P&L | E3: Total P&L | F3: Excess Return(% Total) | G3: Total Return(% Total) | H3: Excess Return(% Deployed) | I3: Total Return(% Deployed)
A4: 4499998 | B4: 1 | C4: 0.0001 | D4: -3744551 | E4: -3798076 | F4: -0.93613775 | G4: -0.949519 | H4: -0.99854693 | I4: -1.0128203
A5: 4499998 | B5: 2 | C5: 0.0002 | D5: -3744551 | E5: -3798076 | F5: -0.93613775 | G5: -0.949519 | H5: -0.99854693 | I5: -1.0128203
A6: 3825126.4 | B6: 3 | C6: 0.0003 | D6: -3069679.4 | E6: -3123204.4 | F6: -0.76741985 | G6: -0.7808011 | H6: -0.81858118 | I6: -0.83285451
A7: 3749998.3 | B7: 4 | C7: 0.0004 | D7: -2994551.3 | E7: -3048076.3 | F7: -0.74863783 | G7: -0.76201908 | H7: -0.79854702 | I7: -0.81282036
A8: 3649685.8 | B8: 5 | C8: 0.0005 | D8: -2894238.8 | E8: -2947763.8 | F8: -0.7235597 | G8: -0.73694095 | H8: -0.77179701 | I8: -0.78607035
A9: 3499998.3 | B9: 6 | C9: 0.0006 | D9: -2744551.3 | E9: -2798076.3 | F9: -0.68613784 | G9: -0.69951909 | H9: -0.73188036 | I9: -0.74615369
A10: 3499998.3 | B10: 7 | C10: 0.0007 | D10: -2744551.3 | E10: -2798076.3 | F10: -0.68613784 | G10: -0.69951909 | H10: -0.73188036 | I10: -0.74615369
A11: 3436532.7 | B11: 8 | C11: 0.0008 | D11: -2681085.7 | E11: -2734610.7 | F11: -0.67027143 | G11: -0.68365268 | H11: -0.71495619 | I11: -0.72922953
A12: 3322639.2 | B12: 9 | C12: 0.0009 | D12: -2567192.2 | E12: -2620717.2 | F12: -0.64179806 | G12: -0.65517931 | H12: -0.68458459 | I12: -0.69885793
A13: 3272442.7 | B13: 10 | C13: 0.001 | D13: -2516995.7 | E13: -2570520.7 | F13: -0.62924893 | G13: -0.64263018 | H13: -0.67119886 | I13: -0.68547219
A14: 3263752.4 | B14: 11 | C14: 0.0011 | D14: -2508305.4 | E14: -2561830.4 | F14: -0.62707635 | G14: -0.6404576 | H14: -0.66888144 | I14: -0.68315478
A15: 3249999.1 | B15: 12 | C15: 0.0012 | D15: -2494552.1 | E15: -2548077.1 | F15: -0.62363804 | G15: -0.63701929 | H15: -0.6652139 | I15: -0.67948724
... A10003: 0 | B10003: 10000 | C10003: 1 | D10003: 755447 | E10003: 701922 | F10003: 0.18886175 | G10003: 0.1754805 | H10003: 0.20145253 | I10003: 0.1871792

Sheet HistoricalEvents
D3: IndustryLoss | E3: EventID | F3: EventName | G3: EventYear | H3: EventType | I3: CB-Bayou Re Ltd. Series 2024-1 Class B Reset 2025 | J3: CB-Bayou Re Ltd. Series 2024-1 Class A Reset 2025 | K3: CB-Bayou Re Ltd. Series 2025-1 Class A | L3: CB-Gateway Re Ltd. Series 2023-1 Class B Reset 2025 | M3: CB-Purple Re Ltd. Series 2024-1 Class A Reset 2025 | N3: CB-Blue Ridge Re Ltd. Series 2023-1 Class A Reset 2025 | O3: CB-Purple Re Ltd. Series 2023-2 Class A Reset 2025 | P3: CB-Charles River Re Ltd. Series 2024-1 Class A Reset 2025 | Q3: CB-3264 Re Ltd. Series 2024-1 Class B Reset 2025 | R3: CB-Citrus Re Ltd. Series 2023-1 Class B Reset 2025 | S3: CB-Bayou Re Ltd. Series 2023-1 Class B Reset 2025 | T3: CB-Baldwin Re Ltd. Series 2023-1 Class A Reset 2025 | U3: CB-Gateway Re Ltd. Series 2023-1 Class A Reset 2025 | V3: Portfolio | W3: CB-Bayou Re Ltd. Series 2023-1 Class A Reset 2025 | X3: CB-Gateway Re Ltd. Series 2025-1 Class A | Y3: CB-Montoya Re Ltd. Series 2025-1 Class B Reset 2025 | Z3: CB-Acorn Re Ltd. Series 2023-1 Class A | AA3: CB-Logistics Re Ltd. Series 2024-1 Class A | AB3: CB-Winston Re Ltd. Series 2024-1 Class A Reset 2025 | AC3: CB-Veraison Re Ltd. Series 2023-1 Class A Reset 2025 | AD3: CB-Winston Re Ltd. Series 2025-1 Class A | AE3: CB-Res Re 2025 Ltd. Series 2025-II Class 2 | AF3: CB-Charles River Re Ltd. Series 2024-1 Class A Reset 2025 | AG3: CB-Citrus Re Ltd. Series 2023-1 Class B Reset 2025 | AH3: CB-Tomoni Re Pte. Ltd. Series 2022-1 Class B-1 Reset 2025 | AI3: CB-Baldwin Re Ltd. Series 2023-1 Class A Reset 2025 | AJ3: Portfolio | AK3: CB-Torrey Pines Re Ltd. Series 2023-1 Class A Reset 2025 | AL3: CB-Bayou Re Ltd. Series 2023-1 Class A Reset 2025 | AM3: CB-Commonwealth Re Ltd. Series 2023-1 Class A Reset 2025 | AN3: CB-Gateway Re Ltd. Series 2025-1 Class C2 | AO3: CB-Black Kite Re Ltd. Series 2025-1 Class A | AP3: CB-Fish Pond Re Ltd. Series 2024-1 Class A Reset 2025 | AQ3: CB-Montoya Re Ltd. Series 2025-1 Class B Reset 2025 | AR3: CB-Nakama Re Pte. Ltd. Series 2024-1 Class 1 Reset 2025 | AS3: CB-Veraison Re Ltd. Series 2025-1 Class A | AT3: CB-Fuchsia 2 Series 2024-1 Class A Reset 2025 | AU3: CB-Lightning Re Ltd. Series 2023-1 Class A Reset 2025 | AV3: CB-FloodSmart Re Ltd. Series 2024-1 Class A Reset 2025_wLMF | AW3: CB-Aragonite Re Ltd. Series 2024-1 Class A Reset 2025 | AX3: CB-Everglades Re II Ltd. Series 2024-1 Class A Reset 2025 | AY3: CB-Maschpark Re Ltd. Series 2024-1 Class A | AZ3: CB-Winston Re Ltd. Series 2024-1 Class B Reset 2025 | BA3: CB-Titania Re Ltd. Series 2023-1 Class A Reset 2025 | BB3: CB-Veraison Re Ltd. Series 2025-1 Class A | BC3: CB-Fuchsia 2 Series 2024-1 Class A Reset 2025 | BD3: CB-Lightning Re Ltd. Series 2023-1 Class A Reset 2025 | BE3: CB-Four Lakes Re Ltd. Series 2023-1 Class B Reset 2025 | BF3: CB-Aragonite Re Ltd. Series 2024-1 Class A Reset 2025 | BG3: CB-Everglades Re II Ltd. Series 2024-1 Class A Reset 2025 | BH3: CB-Maschpark Re Ltd. Series 2024-1 Class A | BI3: CB-Winston Re Ltd. Series 2024-1 Class B Reset 2025 | BJ3: CB-Titania Re Ltd. Series 2023-1 Class A Reset 2025
D4: 5.1288171e+08 | E4: 55951561 | F4: 2012 Waldo Canyon | G4: 9 | H4: 5 | I4: 0 | J4: 0 | K4: 0 | L4: 0 | M4: 0 | N4: 0 | O4: 0 | P4: 0 | Q4: 0 | R4: 0 | S4: 0 | T4: 0 | U4: 0 | V4: 0 | W4: 0 | X4: 0 | Y4: 0 | Z4: 0 | AA4: 0 | AB4: 0 | AC4: 0 | AD4: 0 | AE4: 0 | AF4: 0 | AG4: 0 | AH4: 0 | AI4: 0 | AJ4: 0 | AK4: 0 | AL4: 0 | AM4: 0 | AN4: 0 | AO4: 0 | AP4: 0 | AQ4: 0 | AR4: 0 | AS4: 0 | AT4: 0 | AU4: 0 | AV4: 0 | AW4: 0 | AX4: 0 | AY4: 0 | AZ4: 0 | BA4: 0 | BB4: 0 | BC4: 0 | BD4: 0 | BE4: 0 | BF4: 0 | BG4: 0 | BH4: 0 | BI4: 0 | BJ4: 0
E5: 60098992 | F5: 2016 Yarloop Bushfire | G5: 3 | H5: 6 | I5: 0 | J5: 0 | K5: 0 | L5: 0 | M5: 0 | N5: 0 | O5: 0 | P5: 0 | Q5: 0 | R5: 0 | S5: 0 | T5: 0 | U5: 0 | V5: 0 | W5: 0 | X5: 0 | Y5: 0 | Z5: 0 | AA5: 0 | AB5: 0 | AC5: 0 | AD5: 0 | AE5: 0 | AF5: 0 | AG5: 0 | AH5: 0 | AI5: 0 | AJ5: 0 | AK5: 0 | AL5: 0 | AM5: 0 | AN5: 0 | AO5: 0 | AP5: 0 | AQ5: 0 | AR5: 0 | AS5: 0 | AT5: 0 | AU5: 0 | AV5: 0 | AW5: 0 | AX5: 0 | AY5: 0 | AZ5: 0 | BA5: 0 | BB5: 0 | BC5: 0 | BD5: 0 | BE5: 0 | BF5: 0 | BG5: 0 | BH5: 0 | BI5: 0 | BJ5: 0
E6: 60615059 | F6: 2019 Bunyip Bushfire | G6: 6 | H6: 6 | I6: 0 | J6: 0 | K6: 0 | L6: 0 | M6: 0 | N6: 0 | O6: 0 | P6: 0 | Q6: 0 | R6: 0 | S6: 0 | T6: 0 | U6: 0 | V6: 0 | W6: 0 | X6: 0 | Y6: 0 | Z6: 0 | AA6: 0 | AB6: 0 | AC6: 0 | AD6: 0 | AE6: 0 | AF6: 0 | AG6: 0 | AH6: 0 | AI6: 0 | AJ6: 0 | AK6: 0 | AL6: 0 | AM6: 0 | AN6: 0 | AO6: 0 | AP6: 0 | AQ6: 0 | AR6: 0 | AS6: 0 | AT6: 0 | AU6: 0 | AV6: 0 | AW6: 0 | AX6: 0 | AY6: 0 | AZ6: 0 | BA6: 0 | BB6: 0 | BC6: 0 | BD6: 0 | BE6: 0 | BF6: 0 | BG6: 0 | BH6: 0 | BI6: 0 | BJ6: 0
E7: 60678765 | F7: 1983 Ash Wednesday Bushfire | G7: 1 | H7: 6 | I7: 0 | J7: 0 | K7: 0 | L7: 0 | M7: 0 | N7: 0 | O7: 0 | P7: 0 | Q7: 0 | R7: 0 | S7: 0 | T7: 0 | U7: 0 | V7: 0 | W7: 0 | X7: 0 | Y7: 0 | Z7: 0 | AA7: 0 | AB7: 0 | AC7: 0 | AD7: 0 | AE7: 0 | AF7: 0 | AG7: 0 | AH7: 0 | AI7: 0 | AJ7: 0 | AK7: 0 | AL7: 0 | AM7: 0 | AN7: 0 | AO7: 0 | AP7: 0 | AQ7: 0 | AR7: 0 | AS7: 0 | AT7: 0 | AU7: 0 | AV7: 0 | AW7: 0 | AX7: 0 | AY7: 0 | AZ7: 0 | BA7: 0 | BB7: 0 | BC7: 0 | BD7: 0 | BE7: 0 | BF7: 0 | BG7: 0 | BH7: 0 | BI7: 0 | BJ7: 0
E8: 61179696 | F8: 2018 Tathra Bushfire | G8: 5 | H8: 6 | I8: 0 | J8: 0 | K8: 0 | L8: 0 | M8: 0 | N8: 0 | O8: 0 | P8: 0 | Q8: 0 | R8: 0 | S8: 0 | T8: 0 | U8: 0 | V8: 0 | W8: 0 | X8: 0 | Y8: 0 | Z8: 0 | AA8: 0 | AB8: 0 | AC8: 0 | AD8: 0 | AE8: 0 | AF8: 0 | AG8: 0 | AH8: 0 | AI8: 0 | AJ8: 0 | AK8: 0 | AL8: 0 | AM8: 0 | AN8: 0 | AO8: 0 | AP8: 0 | AQ8: 0 | AR8: 0 | AS8: 0 | AT8: 0 | AU8: 0 | AV8: 0 | AW8: 0 | AX8: 0 | AY8: 0 | AZ8: 0 | BA8: 0 | BB8: 0 | BC8: 0 | BD8: 0 | BE8: 0 | BF8: 0 | BG8: 0 | BH8: 0 | BI8: 0 | BJ8: 0
D9: 8.9098664e+08 | E9: 80439281 | F9: 2011 Tropical Storm Lee | G9: 11 | H9: 8 | I9: 0 | J9: 0 | K9: 0 | L9: 0 | M9: 0 | N9: 0 | O9: 0 | P9: 0 | Q9: 0 | R9: 0 | S9: 0 | T9: 0 | U9: 0 | V9: 0 | W9: 0 | X9: 0 | Y9: 0 | Z9: 0 | AA9: 0 | AB9: 0 | AC9: 0 | AD9: 0 | AE9: 0 | AF9: 0 | AG9: 0 | AH9: 0 | AI9: 0 | AJ9: 0 | AK9: 0 | AL9: 0 | AM9: 0 | AN9: 0 | AO9: 0 | AP9: 0 | AQ9: 0 | AR9: 0 | AS9: 0 | AT9: 0 | AU9: 0 | AV9: 0 | AW9: 0 | AX9: 0 | AY9: 0 | AZ9: 0 | BA9: 0 | BB9: 0 | BC9: 0 | BD9: 0 | BE9: 0 | BF9: 0 | BG9: 0 | BH9: 0 | BI9: 0 | BJ9: 0
D10: 3.4529243e+08 | E10: 110000544 | F10: 1991 Glendale-Arcadia-Sierra Madre CA | G10: 66 | H10: 11 | I10: 0 | J10: 0 | K10: 0 | L10: 0 | M10: 0 | N10: 0 | O10: 0 | P10: 0 | Q10: 0 | R10: 0 | S10: 0 | T10: 0 | U10: 0 | V10: 0 | W10: 0 | X10: 0 | Y10: 0 | Z10: 0 | AA10: 0 | AB10: 0 | AC10: 0 | AD10: 0 | AE10: 0 | AF10: 0 | AG10: 0 | AH10: 0 | AI10: 0 | AJ10: 0 | AK10: 0 | AL10: 0 | AM10: 0 | AN10: 0 | AO10: 0 | AP10: 0 | AQ10: 0 | AR10: 0 | AS10: 0 | AT10: 0 | AU10: 0 | AV10: 0 | AW10: 0 | AX10: 0 | AY10: 0 | AZ10: 0 | BA10: 0 | BB10: 0 | BC10: 0 | BD10: 0 | BE10: 0 | BF10: 0 | BG10: 0 | BH10: 0 | BI10: 0 | BJ10: 0
D11: 3.570069e+08 | E11: 110009851 | F11: 1873 Oregon Coast-Scenario 1 | G11: 17 | H11: 11 | I11: 0 | J11: 0 | K11: 0 | L11: 0 | M11: 0 | N11: 0 | O11: 0 | P11: 0 | Q11: 0 | R11: 0 | S11: 0 | T11: 0 | U11: 0 | V11: 0 | W11: 0 | X11: 0 | Y11: 0 | Z11: 0 | AA11: 0 | AB11: 0 | AC11: 0 | AD11: 0 | AE11: 0 | AF11: 0 | AG11: 0 | AH11: 0 | AI11: 0 | AJ11: 0 | AK11: 0 | AL11: 0 | AM11: 0 | AN11: 0 | AO11: 0 | AP11: 0 | AQ11: 0 | AR11: 0 | AS11: 0 | AT11: 0 | AU11: 0 | AV11: 0 | AW11: 0 | AX11: 0 | AY11: 0 | AZ11: 0 | BA11: 0 | BB11: 0 | BC11: 0 | BD11: 0 | BE11: 0 | BF11: 0 | BG11: 0 | BH11: 0 | BI11: 0 | BJ11: 0
D12: 3.2844716e+08 | E12: 110009851 | F12: 1873 Oregon Coast-Scenario 1 | G12: 17 | H12: 11 | I12: 0 | J12: 0 | K12: 0 | L12: 0 | M12: 0 | N12: 0 | O12: 0 | P12: 0 | Q12: 0 | R12: 0 | S12: 0 | T12: 0 | U12: 0 | V12: 0 | W12: 0 | X12: 0 | Y12: 0 | Z12: 0 | AA12: 0 | AB12: 0 | AC12: 0 | AD12: 0 | AE12: 0 | AF12: 0 | AG12: 0 | AH12: 0 | AI12: 0 | AJ12: 0 | AK12: 0 | AL12: 0 | AM12: 0 | AN12: 0 | AO12: 0 | AP12: 0 | AQ12: 0 | AR12: 0 | AS12: 0 | AT12: 0 | AU12: 0 | AV12: 0 | AW12: 0 | AX12: 0 | AY12: 0 | AZ12: 0 | BA12: 0 | BB12: 0 | BC12: 0 | BD12: 0 | BE12: 0 | BF12: 0 | BG12: 0 | BH12: 0 | BI12: 0 | BJ12: 0
D13: 1.9919565e+08 | E13: 110011943 | F13: 1975 Oroville Reservoir CA | G13: 52 | H13: 11 | I13: 0 | J13: 0 | K13: 0 | L13: 0 | M13: 0 | N13: 0 | O13: 0 | P13: 0 | Q13: 0 | R13: 0 | S13: 0 | T13: 0 | U13: 0 | V13: 0 | W13: 0 | X13: 0 | Y13: 0 | Z13: 0 | AA13: 0 | AB13: 0 | AC13: 0 | AD13: 0 | AE13: 0 | AF13: 0 | AG13: 0 | AH13: 0 | AI13: 0 | AJ13: 0 | AK13: 0 | AL13: 0 | AM13: 0 | AN13: 0 | AO13: 0 | AP13: 0 | AQ13: 0 | AR13: 0 | AS13: 0 | AT13: 0 | AU13: 0 | AV13: 0 | AW13: 0 | AX13: 0 | AY13: 0 | AZ13: 0 | BA13: 0 | BB13: 0 | BC13: 0 | BD13: 0 | BE13: 0 | BF13: 0 | BG13: 0 | BH13: 0 | BI13: 0 | BJ13: 0
D14: 23802576 | E14: 110019370 | F14: 1927 Lompoc CA | G14: 29 | H14: 11 | I14: 0 | J14: 0 | K14: 0 | L14: 0 | M14: 0 | N14: 0 | O14: 0 | P14: 0 | Q14: 0 | R14: 0 | S14: 0 | T14: 0 | U14: 0 | V14: 0 | W14: 0 | X14: 0 | Y14: 0 | Z14: 0 | AA14: 0 | AB14: 0 | AC14: 0 | AD14: 0 | AE14: 0 | AF14: 0 | AG14: 0 | AH14: 0 | AI14: 0 | AJ14: 0 | AK14: 0 | AL14: 0 | AM14: 0 | AN14: 0 | AO14: 0 | AP14: 0 | AQ14: 0 | AR14: 0 | AS14: 0 | AT14: 0 | AU14: 0 | AV14: 0 | AW14: 0 | AX14: 0 | AY14: 0 | AZ14: 0 | BA14: 0 | BB14: 0 | BC14: 0 | BD14: 0 | BE14: 0 | BF14: 0 | BG14: 0 | BH14: 0 | BI14: 0 | BJ14: 0
D15: 887583.48 | E15: 110024122 | F15: 1899 Yakutat Bay AK | G15: 20 | H15: 11 | I15: 0 | J15: 0 | K15: 0 | L15: 0 | M15: 0 | N15: 0 | O15: 0 | P15: 0 | Q15: 0 | R15: 0 | S15: 0 | T15: 0 | U15: 0 | V15: 0 | W15: 0 | X15: 0 | Y15: 0 | Z15: 0 | AA15: 0 | AB15: 0 | AC15: 0 | AD15: 0 | AE15: 0 | AF15: 0 | AG15: 0 | AH15: 0 | AI15: 0 | AJ15: 0 | AK15: 0 | AL15: 0 | AM15: 0 | AN15: 0 | AO15: 0 | AP15: 0 | AQ15: 0 | AR15: 0 | AS15: 0 | AT15: 0 | AU15: 0 | AV15: 0 | AW15: 0 | AX15: 0 | AY15: 0 | AZ15: 0 | BA15: 0 | BB15: 0 | BC15: 0 | BD15: 0 | BE15: 0 | BF15: 0 | BG15: 0 | BH15: 0 | BI15: 0 | BJ15: 0
D16: 41473500 | E16: 110058772 | F16: 1949 Offshore of Haida Gwaii/Queen Charlotte Islands BC | G16: 38 | H16: 11 | I16: 0 | J16: 0 | K16: 0 | L16: 0 | M16: 0 | N16: 0 | O16: 0 | P16: 0 | Q16: 0 | R16: 0 | S16: 0 | T16: 0 | U16: 0 | V16: 0 | W16: 0 | X16: 0 | Y16: 0 | Z16: 0 | AA16: 0 | AB16: 0 | AC16: 0 | AD16: 0 | AE16: 0 | AF16: 0 | AG16: 0 | AH16: 0 | AI16: 0 | AJ16: 0 | AK16: 0 | AL16: 0 | AM16: 0 | AN16: 0 | AO16: 0 | AP16: 0 | AQ16: 0 | AR16: 0 | AS16: 0 | AT16: 0 | AU16: 0 | AV16: 0 | AW16: 0 | AX16: 0 | AY16: 0 | AZ16: 0 | BA16: 0 | BB16: 0 | BC16: 0 | BD16: 0 | BE16: 0 | BF16: 0 | BG16: 0 | BH16: 0 | BI16: 0 | BJ16: 0
D17: 2834863.4 | E17: 110062060 | F17: 1986 Paicines-San Banito CA | G17: 61 | H17: 11 | I17: 0 | J17: 0 | K17: 0 | L17: 0 | M17: 0 | N17: 0 | O17: 0 | P17: 0 | Q17: 0 | R17: 0 | S17: 0 | T17: 0 | U17: 0 | V17: 0 | W17: 0 | X17: 0 | Y17: 0 | Z17: 0 | AA17: 0 | AB17: 0 | AC17: 0 | AD17: 0 | AE17: 0 | AF17: 0 | AG17: 0 | AH17: 0 | AI17: 0 | AJ17: 0 | AK17: 0 | AL17: 0 | AM17: 0 | AN17: 0 | AO17: 0 | AP17: 0 | AQ17: 0 | AR17: 0 | AS17: 0 | AT17: 0 | AU17: 0 | AV17: 0 | AW17: 0 | AX17: 0 | AY17: 0 | AZ17: 0 | BA17: 0 | BB17: 0 | BC17: 0 | BD17: 0 | BE17: 0 | BF17: 0 | BG17: 0 | BH17: 0 | BI17: 0 | BJ17: 0
D18: 26585281 | E18: 110062287 | F18: 1904 Passamaquoddy Bay NB | G18: 21 | H18: 11 | I18: 0 | J18: 0 | K18: 0 | L18: 0 | M18: 0 | N18: 0 | O18: 0 | P18: 0 | Q18: 0 | R18: 0 | S18: 0 | T18: 0 | U18: 0 | V18: 0 | W18: 0 | X18: 0 | Y18: 0 | Z18: 0 | AA18: 0 | AB18: 0 | AC18: 0 | AD18: 0 | AE18: 0 | AF18: 0 | AG18: 0 | AH18: 0 | AI18: 0 | AJ18: 0 | AK18: 0 | AL18: 0 | AM18: 0 | AN18: 0 | AO18: 0 | AP18: 0 | AQ18: 0 | AR18: 0 | AS18: 0 | AT18: 0 | AU18: 0 | AV18: 0 | AW18: 0 | AX18: 0 | AY18: 0 | AZ18: 0 | BA18: 0 | BB18: 0 | BC18: 0 | BD18: 0 | BE18: 0 | BF18: 0 | BG18: 0 | BH18: 0 | BI18: 0 | BJ18: 0
D19: 18038605256 | E19: 110069846 | F19: 1812 Wrightwood CA | G19: 8 | H19: 11 | I19: 0 | J19: 0 | K19: 0 | L19: 0 | M19: 0 | N19: 0 | O19: 0 | P19: 0 | Q19: 0 | R19: 0 | S19: 0 | T19: 0 | U19: 0 | V19: 0 | W19: 0 | X19: 0 | Y19: 0 | Z19: 0 | AA19: 0 | AB19: 0 | AC19: 0 | AD19: 0 | AE19: 0 | AF19: 0 | AG19: 0 | AH19: 0 | AI19: 0 | AJ19: 0 | AK19: 0 | AL19: 0 | AM19: 0 | AN19: 0 | AO19: 0 | AP19: 0 | AQ19: 0 | AR19: 0 | AS19: 0 | AT19: 0 | AU19: 0 | AV19: 0 | AW19: 0 | AX19: 0 | AY19: 0 | AZ19: 0 | BA19: 0 | BB19: 0 | BC19: 0 | BD19: 0 | BE19: 0 | BF19: 0 | BG19: 0 | BH19: 0 | BI19: 0 | BJ19: 0
D20: 2.78213e+08 | E20: 110071633 | F20: 1992 Landers-Yucca Valley CA | G20: 67 | H20: 11 | I20: 0 | J20: 0 | K20: 0 | L20: 0 | M20: 0 | N20: 0 | O20: 0 | P20: 0 | Q20: 0 | R20: 0 | S20: 0 | T20: 0 | U20: 0 | V20: 0 | W20: 0 | X20: 0 | Y20: 0 | Z20: 0 | AA20: 0 | AB20: 0 | AC20: 0 | AD20: 0 | AE20: 0 | AF20: 0 | AG20: 0 | AH20: 0 | AI20: 0 | AJ20: 0 | AK20: 0 | AL20: 0 | AM20: 0 | AN20: 0 | AO20: 0 | AP20: 0 | AQ20: 0 | AR20: 0 | AS20: 0 | AT20: 0 | AU20: 0 | AV20: 0 | AW20: 0 | AX20: 0 | AY20: 0 | AZ20: 0 | BA20: 0 | BB20: 0 | BC20: 0 | BD20: 0 | BE20: 0 | BF20: 0 | BG20: 0 | BH20: 0 | BI20: 0 | BJ20: 0
... D26: 3.6804797e+08 | E26: 190237570 | F26: 2020 Fort McMurray Ice Jam Flood | G26: 6 | H26: 19 | I26: 0 | J26: 0 | K26: 0 | L26: 0 | M26: 0 | N26: 0 | O26: 0 | P26: 0 | Q26: 0 | R26: 0 | S26: 0 | T26: 0 | U26: 0 | V26: 0 | W26: 0 | X26: 0 | Y26: 0 | Z26: 0 | AA26: 0 | AB26: 0 | AC26: 0 | AD26: 0 | AE26: 0 | AF26: 0 | AG26: 0 | AH26: 0 | AI26: 0 | AJ26: 0 | AK26: 0 | AL26: 0 | AM26: 0 | AN26: 0 | AO26: 0 | AP26: 0 | AQ26: 0 | AR26: 0 | AS26: 0 | AT26: 0 | AU26: 0 | AV26: 0 | AW26: 0 | AX26: 0 | AY26: 0 | AZ26: 0 | BA26: 0 | BB26: 0 | BC26: 0 | BD26: 0 | BE26: 0 | BF26: 0 | BG26: 0 | BH26: 0 | BI26: 0 | BJ26: 0
E27: 221642484 | F27: MidwestOutbreak_PCS18_5 | G27: 15 | H27: 22 | I27: 0 | J27: 0 | K27: 0 | L27: 0 | M27: 0 | N27: 0 | O27: 0 | P27: 0 | Q27: 0 | R27: 0 | S27: 0 | T27: 0 | U27: 0 | V27: 0 | W27: 0 | X27: 0 | Y27: 0 | Z27: 0 | AA27: 0 | AB27: 0 | AC27: 0 | AD27: 0 | AE27: 0 | AF27: 0 | AG27: 0 | AH27: 0 | AI27: 0 | AJ27: 0 | AK27: 0 | AL27: 0 | AM27: 0 | AN27: 0 | AO27: 0 | AP27: 0 | AQ27: 0 | AR27: 0 | AS27: 0 | AT27: 0 | AU27: 0 | AV27: 0 | AW27: 0 | AX27: 0 | AY27: 0 | AZ27: 0 | BA27: 0 | BB27: 0 | BC27: 0 | BD27: 0 | BE27: 0 | BF27: 0 | BG27: 0 | BH27: 0 | BI27: 0 | BJ27: 0
D28: 1.5300437e+09 | E28: 270003198 | F28: 1999 Lenny | G28: 44 | H28: 27 | I28: 0 | J28: 0 | K28: 0 | L28: 0 | M28: 0 | N28: 0 | O28: 0 | P28: 0 | Q28: 0 | R28: 0 | S28: 0 | T28: 0 | U28: 0 | V28: 0 | W28: 0 | X28: 0 | Y28: 0 | Z28: 0 | AA28: 0 | AB28: 0 | AC28: 0 | AD28: 0 | AE28: 0 | AF28: 0 | AG28: 0 | AH28: 0 | AI28: 0 | AJ28: 0 | AK28: 0 | AL28: 0 | AM28: 0 | AN28: 0 | AO28: 0 | AP28: 0 | AQ28: 0 | AR28: 0 | AS28: 0 | AT28: 0 | AU28: 0 | AV28: 0 | AW28: 0 | AX28: 0 | AY28: 0 | AZ28: 0 | BA28: 0 | BB28: 0 | BC28: 0 | BD28: 0 | BE28: 0 | BF28: 0 | BG28: 0 | BH28: 0 | BI28: 0 | BJ28: 0
D29: 6.6468185e+09 | E29: 270016896 | F29: 2011 Irene | G29: 53 | H29: 27 | I29: 0 | J29: 0 | K29: 0 | L29: 0 | M29: 0 | N29: 0 | O29: 0 | P29: 0 | Q29: 0 | R29: 0 | S29: 0 | T29: 0 | U29: 0 | V29: 0 | W29: 0 | X29: 0 | Y29: 0 | Z29: 0 | AA29: 0 | AB29: 0 | AC29: 0 | AD29: 0 | AE29: 0 | AF29: 0 | AG29: 0 | AH29: 0 | AI29: 0 | AJ29: 0 | AK29: 0 | AL29: 0 | AM29: 0 | AN29: 0 | AO29: 0 | AP29: 0 | AQ29: 0 | AR29: 0 | AS29: 0 | AT29: 0 | AU29: 0 | AV29: 0 | AW29: 0 | AX29: 0 | AY29: 0 | AZ29: 0 | BA29: 0 | BB29: 0 | BC29: 0 | BD29: 0 | BE29: 0 | BF29: 0 | BG29: 0 | BH29: 0 | BI29: 0 | BJ29: 0
D30: 2.9934117e+09 | E30: 270028025 | F30: 2020 Hurricane Sally | G30: 59 | H30: 27 | I30: 0 | J30: 0 | K30: 0 | L30: 0 | M30: 0 | N30: 0 | O30: 0 | P30: 0 | Q30: 0 | R30: 0 | S30: 0 | T30: 0 | U30: 0 | V30: 0 | W30: 0 | X30: 0 | Y30: 0 | Z30: 0 | AA30: 0 | AB30: 0 | AC30: 0 | AD30: 0 | AE30: 0 | AF30: 0 | AG30: 0 | AH30: 0 | AI30: 0 | AJ30: 0 | AK30: 0 | AL30: 0 | AM30: 0 | AN30: 0 | AO30: 0 | AP30: 0 | AQ30: 0 | AR30: 0 | AS30: 0 | AT30: 0 | AU30: 0 | AV30: 0 | AW30: 0 | AX30: 0 | AY30: 0 | AZ30: 0 | BA30: 0 | BB30: 0 | BC30: 0 | BD30: 0 | BE30: 0 | BF30: 0 | BG30: 0 | BH30: 0 | BI30: 0 | BJ30: 0
D31: 3.1161323e+08 | E31: 270029073 | F31: 2016 Hermine | G31: 56 | H31: 27 | I31: 0 | J31: 0 | K31: 0 | L31: 0 | M31: 0 | N31: 0 | O31: 0 | P31: 0 | Q31: 0 | R31: 0 | S31: 0 | T31: 0 | U31: 0 | V31: 0 | W31: 0 | X31: 0 | Y31: 0 | Z31: 0 | AA31: 0 | AB31: 0 | AC31: 0 | AD31: 0 | AE31: 0 | AF31: 0 | AG31: 0 | AH31: 0 | AI31: 0 | AJ31: 0 | AK31: 0 | AL31: 0 | AM31: 0 | AN31: 0 | AO31: 0 | AP31: 0 | AQ31: 0 | AR31: 0 | AS31: 0 | AT31: 0 | AU31: 0 | AV31: 0 | AW31: 0 | AX31: 0 | AY31: 0 | AZ31: 0 | BA31: 0 | BB31: 0 | BC31: 0 | BD31: 0 | BE31: 0 | BF31: 0 | BG31: 0 | BH31: 0 | BI31: 0 | BJ31: 0
D32: 8.9256974e+10 | E32: 270077773 | F32: 1992 Andrew | G32: 37 | H32: 27 | I32: 0 | J32: 0 | K32: 0 | L32: 0 | M32: 0 | N32: 0 | O32: 0 | P32: 0 | Q32: 60198.824 | R32: 0 | S32: 0 | T32: 0 | U32: 0 | V32: 60198.824 | W32: 0 | X32: 0 | Y32: 0 | Z32: 0 | AA32: 0 | AB32: 0 | AC32: 0 | AD32: 0 | AE32: 0 | AF32: 0 | AG32: 0 | AH32: 0 | AI32: 0 | AJ32: 250002 | AK32: 0 | AL32: 0 | AM32: 0 | AN32: 0 | AO32: 0 | AP32: 0 | AQ32: 0 | AR32: 0 | AS32: 0 | AT32: 0 | AU32: 0 | AV32: 250002 | AW32: 0 | AX32: 0 | AY32: 0 | AZ32: 0 | BA32: 0 | BB32: 0 | BC32: 0 | BD32: 0 | BE32: 0 | BF32: 0 | BG32: 0 | BH32: 0 | BI32: 0 | BJ32: 0
D33: 3.2673448e+10 | E33: 270132852 | F33: 2012 Sandy | G33: 54 | H33: 27 | I33: 0 | J33: 0 | K33: 0 | L33: 0 | M33: 0 | N33: 0 | O33: 0 | P33: 69604.262 | Q33: 0 | R33: 0 | S33: 0 | T33: 0 | U33: 0 | V33: 69604.262 | W33: 0 | X33: 0 | Y33: 0 | Z33: 0 | AA33: 0 | AB33: 0 | AC33: 0 | AD33: 0 | AE33: 126181.26 | AF33: 250000 | AG33: 249999.65 | AH33: 0 | AI33: 250000 | AJ33: 1912503.1 | AK33: 0 | AL33: 0 | AM33: 250000.5 | AN33: 0 | AO33: 0 | AP33: 0 | AQ33: 0 | AR33: 0 | AS33: 0 | AT33: 0 | AU33: 0 | AV33: 0 | AW33: 0 | AX33: 0 | AY33: 0 | AZ33: 0 | BA33: 0 | BB33: 0 | BC33: 0 | BD33: 0 | BE33: 0 | BF33: 0 | BG33: 0 | BH33: 0 | BI33: 0 | BJ33: 0
D34: 5.7938128e+09 | E34: 270140848 | F34: 1935 Event 6 Florida | G34: 11 | H34: 27 | I34: 0 | J34: 0 | K34: 0 | L34: 0 | M34: 0 | N34: 0 | O34: 0 | P34: 0 | Q34: 0 | R34: 0 | S34: 0 | T34: 0 | U34: 0 | V34: 0 | W34: 0 | X34: 0 | Y34: 0 | Z34: 0 | AA34: 0 | AB34: 0 | AC34: 0 | AD34: 0 | AE34: 0 | AF34: 0 | AG34: 0 | AH34: 0 | AI34: 0 | AJ34: 0 | AK34: 0 | AL34: 0 | AM34: 0 | AN34: 0 | AO34: 0 | AP34: 0 | AQ34: 0 | AR34: 0 | AS34: 0 | AT34: 0 | AU34: 0 | AV34: 0 | AW34: 0 | AX34: 0 | AY34: 0 | AZ34: 0 | BA34: 0 | BB34: 0 | BC34: 0 | BD34: 0 | BE34: 0 | BF34: 0 | BG34: 0 | BH34: 0 | BI34: 0 | BJ34: 0
D35: 3.4583652e+10 | E35: 270144918 | F35: 2005 Wilma (US loss) | G35: 50 | H35: 27 | I35: 0 | J35: 0 | K35: 0 | L35: 0 | M35: 0 | N35: 0 | O35: 0 | P35: 0 | Q35: 0 | R35: 0 | S35: 0 | T35: 0 | U35: 0 | V35: 0 | W35: 0 | X35: 0 | Y35: 0 | Z35: 0 | AA35: 0 | AB35: 0 | AC35: 0 | AD35: 0 | AE35: 0 | AF35: 0 | AG35: 0 | AH35: 0 | AI35: 0 | AJ35: 0 | AK35: 0 | AL35: 0 | AM35: 0 | AN35: 0 | AO35: 0 | AP35: 0 | AQ35: 0 | AR35: 0 | AS35: 0 | AT35: 0 | AU35: 0 | AV35: 0 | AW35: 0 | AX35: 0 | AY35: 0 | AZ35: 0 | BA35: 0 | BB35: 0 | BC35: 0 | BD35: 0 | BE35: 0 | BF35: 0 | BG35: 0 | BH35: 0 | BI35: 0 | BJ35: 0
D36: 3.8486484e+10 | E36: 270150496 | F36: 1944 Event 11 Florida | G36: 15 | H36: 27 | I36: 0 | J36: 0 | K36: 0 | L36: 0 | M36: 0 | N36: 0 | O36: 0 | P36: 0 | Q36: 0 | R36: 0 | S36: 0 | T36: 0 | U36: 0 | V36: 0 | W36: 0 | X36: 0 | Y36: 0 | Z36: 0 | AA36: 0 | AB36: 0 | AC36: 0 | AD36: 0 | AE36: 0 | AF36: 0 | AG36: 0 | AH36: 0 | AI36: 0 | AJ36: 0 | AK36: 0 | AL36: 0 | AM36: 0 | AN36: 0 | AO36: 0 | AP36: 0 | AQ36: 0 | AR36: 0 | AS36: 0 | AT36: 0 | AU36: 0 | AV36: 0 | AW36: 0 | AX36: 0 | AY36: 0 | AZ36: 0 | BA36: 0 | BB36: 0 | BC36: 0 | BD36: 0 | BE36: 0 | BF36: 0 | BG36: 0 | BH36: 0 | BI36: 0 | BJ36: 0
D37: 1.7325172e+10 | E37: 270184270 | F37: 2017 Maria | G37: 57 | H37: 27 | I37: 0 | J37: 0 | K37: 0 | L37: 0 | M37: 0 | N37: 0 | O37: 0 | P37: 0 | Q37: 0 | R37: 0 | S37: 0 | T37: 0 | U37: 0 | V37: 0 | W37: 0 | X37: 0 | Y37: 0 | Z37: 0 | AA37: 0 | AB37: 0 | AC37: 0 | AD37: 0 | AE37: 0 | AF37: 0 | AG37: 0 | AH37: 0 | AI37: 0 | AJ37: 0 | AK37: 0 | AL37: 0 | AM37: 0 | AN37: 0 | AO37: 0 | AP37: 0 | AQ37: 0 | AR37: 0 | AS37: 0 | AT37: 0 | AU37: 0 | AV37: 0 | AW37: 0 | AX37: 0 | AY37: 0 | AZ37: 0 | BA37: 0 | BB37: 0 | BC37: 0 | BD37: 0 | BE37: 0 | BF37: 0 | BG37: 0 | BH37: 0 | BI37: 0 | BJ37: 0
D38: 1.3974705e+10 | E38: 270201984 | F38: 1979 Frederic | G38: 30 | H38: 27 | I38: 0 | J38: 0 | K38: 0 | L38: 0 | M38: 0 | N38: 0 | O38: 0 | P38: 0 | Q38: 0 | R38: 0 | S38: 0 | T38: 0 | U38: 0 | V38: 0 | W38: 0 | X38: 0 | Y38: 0 | Z38: 0 | AA38: 0 | AB38: 0 | AC38: 0 | AD38: 0 | AE38: 0 | AF38: 0 | AG38: 0 | AH38: 0 | AI38: 0 | AJ38: 0 | AK38: 0 | AL38: 0 | AM38: 0 | AN38: 0 | AO38: 0 | AP38: 0 | AQ38: 0 | AR38: 0 | AS38: 0 | AT38: 0 | AU38: 0 | AV38: 0 | AW38: 0 | AX38: 0 | AY38: 0 | AZ38: 0 | BA38: 0 | BB38: 0 | BC38: 0 | BD38: 0 | BE38: 0 | BF38: 0 | BG38: 0 | BH38: 0 | BI38: 0 | BJ38: 0
D39: 3.4594641e+08 | E39: 270228712 | F39: 2003 Claudette | G39: 48 | H39: 27 | I39: 0 | J39: 0 | K39: 0 | L39: 0 | M39: 0 | N39: 0 | O39: 0 | P39: 0 | Q39: 0 | R39: 0 | S39: 0 | T39: 0 | U39: 0 | V39: 0 | W39: 0 | X39: 0 | Y39: 0 | Z39: 0 | AA39: 0 | AB39: 0 | AC39: 0 | AD39: 0 | AE39: 0 | AF39: 0 | AG39: 0 | AH39: 0 | AI39: 0 | AJ39: 0 | AK39: 0 | AL39: 0 | AM39: 0 | AN39: 0 | AO39: 0 | AP39: 0 | AQ39: 0 | AR39: 0 | AS39: 0 | AT39: 0 | AU39: 0 | AV39: 0 | AW39: 0 | AX39: 0 | AY39: 0 | AZ39: 0 | BA39: 0 | BB39: 0 | BC39: 0 | BD39: 0 | BE39: 0 | BF39: 0 | BG39: 0 | BH39: 0 | BI39: 0 | BJ39: 0
... D103: 6.6853748e+08 | E103: 56576525 | F103: 2020 Almeda Drive | G103: 14 | H103: 5 | I103: 0 | J103: 0 | K103: 0 | L103: 0 | M103: 0 | N103: 0 | O103: 0 | P103: 0 | Q103: 0 | R103: 0 | S103: 0 | T103: 0 | U103: 0 | V103: 0 | W103: 0 | X103: 0 | Y103: 0 | Z103: 0 | AA103: 0 | AB103: 0 | AC103: 0 | AD103: 0 | AE103: 0 | AF103: 0 | AG103: 0 | AH103: 0 | AI103: 0 | AJ103: 0 | AK103: 0 | AL103: 0 | AM103: 0 | AN103: 0 | AO103: 0 | AP103: 0 | AQ103: 0 | AR103: 0 | AS103: 0 | AT103: 0 | AU103: 0 | AV103: 0 | AW103: 0 | AX103: 0 | AY103: 0 | AZ103: 0 | BA103: 0 | BB103: 0 | BC103: 0 | BD103: 0 | BE103: 0 | BF103: 0 | BG103: 0 | BH103: 0 | BI103: 0 | BJ103: 0
E104: 60814971 | F104: 2017 Sir Ivan and Carwoola Bushfire | G104: 4 | H104: 6 | I104: 0 | J104: 0 | K104: 0 | L104: 0 | M104: 0 | N104: 0 | O104: 0 | P104: 0 | Q104: 0 | R104: 0 | S104: 0 | T104: 0 | U104: 0 | V104: 0 | W104: 0 | X104: 0 | Y104: 0 | Z104: 0 | AA104: 0 | AB104: 0 | AC104: 0 | AD104: 0 | AE104: 0 | AF104: 0 | AG104: 0 | AH104: 0 | AI104: 0 | AJ104: 0 | AK104: 0 | AL104: 0 | AM104: 0 | AN104: 0 | AO104: 0 | AP104: 0 | AQ104: 0 | AR104: 0 | AS104: 0 | AT104: 0 | AU104: 0 | AV104: 0 | AW104: 0 | AX104: 0 | AY104: 0 | AZ104: 0 | BA104: 0 | BB104: 0 | BC104: 0 | BD104: 0 | BE104: 0 | BF104: 0 | BG104: 0 | BH104: 0 | BI104: 0 | BJ104: 0
D105: 4.2342111e+09 | E105: 80006364 | F105: 2001 Tropical Storm Alisson | G105: 6 | H105: 8 | I105: 0 | J105: 0 | K105: 0 | L105: 0 | M105: 0 | N105: 0 | O105: 0 | P105: 0 | Q105: 0 | R105: 0 | S105: 0 | T105: 0 | U105: 0 | V105: 0 | W105: 0 | X105: 0 | Y105: 0 | Z105: 0 | AA105: 0 | AB105: 0 | AC105: 0 | AD105: 0 | AE105: 0 | AF105: 0 | AG105: 0 | AH105: 0 | AI105: 0 | AJ105: 0 | AK105: 0 | AL105: 0 | AM105: 0 | AN105: 0 | AO105: 0 | AP105: 0 | AQ105: 0 | AR105: 0 | AS105: 0 | AT105: 0 | AU105: 0 | AV105: 0 | AW105: 0 | AX105: 0 | AY105: 0 | AZ105: 0 | BA105: 0 | BB105: 0 | BC105: 0 | BD105: 0 | BE105: 0 | BF105: 0 | BG105: 0 | BH105: 0 | BI105: 0 | BJ105: 0
D106: 1.5345066e+09 | E106: 80127142 | F106: 1995 California Flood | G106: 2 | H106: 8 | I106: 0 | J106: 0 | K106: 0 | L106: 0 | M106: 0 | N106: 0 | O106: 0 | P106: 0 | Q106: 0 | R106: 0 | S106: 0 | T106: 0 | U106: 0 | V106: 0 | W106: 0 | X106: 0 | Y106: 0 | Z106: 0 | AA106: 0 | AB106: 0 | AC106: 0 | AD106: 0 | AE106: 0 | AF106: 0 | AG106: 0 | AH106: 0 | AI106: 0 | AJ106: 0 | AK106: 0 | AL106: 0 | AM106: 0 | AN106: 0 | AO106: 0 | AP106: 0 | AQ106: 0 | AR106: 0 | AS106: 0 | AT106: 0 | AU106: 0 | AV106: 0 | AW106: 0 | AX106: 0 | AY106: 0 | AZ106: 0 | BA106: 0 | BB106: 0 | BC106: 0 | BD106: 0 | BE106: 0 | BF106: 0 | BG106: 0 | BH106: 0 | BI106: 0 | BJ106: 0
D107: 177423.09 | E107: 110003338 | F107: 1958 Lituya Bay AK | G107: 43 | H107: 11 | I107: 0 | J107: 0 | K107: 0 | L107: 0 | M107: 0 | N107: 0 | O107: 0 | P107: 0 | Q107: 0 | R107: 0 | S107: 0 | T107: 0 | U107: 0 | V107: 0 | W107: 0 | X107: 0 | Y107: 0 | Z107: 0 | AA107: 0 | AB107: 0 | AC107: 0 | AD107: 0 | AE107: 0 | AF107: 0 | AG107: 0 | AH107: 0 | AI107: 0 | AJ107: 0 | AK107: 0 | AL107: 0 | AM107: 0 | AN107: 0 | AO107: 0 | AP107: 0 | AQ107: 0 | AR107: 0 | AS107: 0 | AT107: 0 | AU107: 0 | AV107: 0 | AW107: 0 | AX107: 0 | AY107: 0 | AZ107: 0 | BA107: 0 | BB107: 0 | BC107: 0 | BD107: 0 | BE107: 0 | BF107: 0 | BG107: 0 | BH107: 0 | BI107: 0 | BJ107: 0
D108: 9.0357654e+10 | E108: 110011195 | F108: 1812 New Madrid Seismic Zone-Scenario 4-3 Segments Rupture | G108: 8 | H108: 11 | I108: 0 | J108: 0 | K108: 0 | L108: 0 | M108: 0 | N108: 0 | O108: 0 | P108: 0 | Q108: 0 | R108: 0 | S108: 0 | T108: 0 | U108: 0 | V108: 0 | W108: 0 | X108: 0 | Y108: 0 | Z108: 0 | AA108: 0 | AB108: 0 | AC108: 0 | AD108: 0 | AE108: 0 | AF108: 0 | AG108: 0 | AH108: 0 | AI108: 0 | AJ108: 0 | AK108: 0 | AL108: 0 | AM108: 0 | AN108: 0 | AO108: 0 | AP108: 0 | AQ108: 0 | AR108: 0 | AS108: 0 | AT108: 0 | AU108: 0 | AV108: 0 | AW108: 0 | AX108: 0 | AY108: 0 | AZ108: 0 | BA108: 0 | BB108: 0 | BC108: 0 | BD108: 0 | BE108: 0 | BF108: 0 | BG108: 0 | BH108: 0 | BI108: 0 | BJ108: 0
D109: 45931856 | E109: 110015411 | F109: 1992 Petrolia-Cape Mendocino CA | G109: 67 | H109: 11 | I109: 0 | J109: 0 | K109: 0 | L109: 0 | M109: 0 | N109: 0 | O109: 0 | P109: 0 | Q109: 0 | R109: 0 | S109: 0 | T109: 0 | U109: 0 | V109: 0 | W109: 0 | X109: 0 | Y109: 0 | Z109: 0 | AA109: 0 | AB109: 0 | AC109: 0 | AD109: 0 | AE109: 0 | AF109: 0 | AG109: 0 | AH109: 0 | AI109: 0 | AJ109: 0 | AK109: 0 | AL109: 0 | AM109: 0 | AN109: 0 | AO109: 0 | AP109: 0 | AQ109: 0 | AR109: 0 | AS109: 0 | AT109: 0 | AU109: 0 | AV109: 0 | AW109: 0 | AX109: 0 | AY109: 0 | AZ109: 0 | BA109: 0 | BB109: 0 | BC109: 0 | BD109: 0 | BE109: 0 | BF109: 0 | BG109: 0 | BH109: 0 | BI109: 0 | BJ109: 0
D110: 4.3303971e+08 | E110: 110017483 | F110: 1860 Charlevoix-Kamouraska region QC | G110: 12 | H110: 11 | I110: 0 | J110: 0 | K110: 0 | L110: 0 | M110: 0 | N110: 0 | O110: 0 | P110: 0 | Q110: 0 | R110: 0 | S110: 0 | T110: 0 | U110: 0 | V110: 0 | W110: 0 | X110: 0 | Y110: 0 | Z110: 0 | AA110: 0 | AB110: 0 | AC110: 0 | AD110: 0 | AE110: 0 | AF110: 0 | AG110: 0 | AH110: 0 | AI110: 0 | AJ110: 0 | AK110: 0 | AL110: 0 | AM110: 0 | AN110: 0 | AO110: 0 | AP110: 0 | AQ110: 0 | AR110: 0 | AS110: 0 | AT110: 0 | AU110: 0 | AV110: 0 | AW110: 0 | AX110: 0 | AY110: 0 | AZ110: 0 | BA110: 0 | BB110: 0 | BC110: 0 | BD110: 0 | BE110: 0 | BF110: 20528.103 | BG110: 0 | BH110: 0 | BI110: 0 | BJ110: 0
...

Sheet CorrMxData
A1: ILSName | B1: ILSName2 | C1: Aggtype | D1: Year | E1: AggLoss
A2: CB-Baldwin Re Ltd. Series 2023-1 Class A Reset 2025 | C2: AEPCOTVAR | D2: 100 | E2: 749999.99
A3: CB-Baldwin Re Ltd. Series 2023-1 Class A Reset 2025 | B3: CB-Baldwin Re Ltd. Series 2023-1 Class A Reset 2025 | C3: AEPCOTVAR | D3: 100 | E3: 1500000
A4: CB-Baldwin Re Ltd. Series 2023-1 Class A Reset 2025 | B4: CB-Baldwin Re Ltd. Series 2023-1 Class A Reset 2025 | C4: AEPCOTVAR | D4: 100 | E4: 1500000
A5: CB-Baldwin Re Ltd. Series 2023-1 Class A Reset 2025 | B5: CB-Gateway Re Ltd. Series 2025-1 Class A | C5: AEPCOTVAR | D5: 100 | E5: 795818.1
A6: CB-Baldwin Re Ltd. Series 2023-1 Class A Reset 2025 | B6: CB-3264 Re Ltd. Series 2024-1 Class B Reset 2025 | C6: AEPCOTVAR | D6: 100 | E6: 764076.34
A7: CB-Baldwin Re Ltd. Series 2023-1 Class A Reset 2025 | B7: CB-Citrus Re Ltd. Series 2023-1 Class B Reset 2025 | C7: AEPCOTVAR | D7: 100 | E7: 894856.25
A8: CB-Baldwin Re Ltd. Series 2023-1 Class A Reset 2025 | B8: CB-Blue Ridge Re Ltd. Series 2023-1 Class A Reset 2025 | C8: AEPCOTVAR | D8: 100 | E8: 763579.4
A9: CB-Baldwin Re Ltd. Series 2023-1 Class A Reset 2025 | B9: CB-Bayou Re Ltd. Series 2023-1 Class A Reset 2025 | C9: AEPCOTVAR | D9: 100 | E9: 778777.34
A10: CB-Baldwin Re Ltd. Series 2023-1 Class A Reset 2025 | B10: CB-Bayou Re Ltd. Series 2023-1 Class A Reset 2025 | C10: AEPCOTVAR | D10: 100 | E10: 778777.34
A11: CB-Baldwin Re Ltd. Series 2023-1 Class A Reset 2025 | B11: CB-Bayou Re Ltd. Series 2023-1 Class B Reset 2025 | C11: AEPCOTVAR | D11: 100 | E11: 769555.77
A12: CB-Baldwin Re Ltd. Series 2023-1 Class A Reset 2025 | B12: CB-Purple Re Ltd. Series 2024-1 Class A Reset 2025 | C12: AEPCOTVAR | D12: 100 | E12: 755000.01
A13: CB-Baldwin Re Ltd. Series 2023-1 Class A Reset 2025 | B13: CB-Purple Re Ltd. Series 2023-2 Class A Reset 2025 | C13: AEPCOTVAR | D13: 100 | E13: 754999.99
A14: CB-Baldwin Re Ltd. Series 2023-1 Class A Reset 2025 | B14: CB-Bayou Re Ltd. Series 2024-1 Class A Reset 2025 | C14: AEPCOTVAR | D14: 100 | E14: 757499.99
... A21: CB-Baldwin Re Ltd. Series 2023-1 Class A Reset 2025 | B21: CB-Montoya Re Ltd. Series 2025-1 Class B Reset 2025 | C21: AEPCOTVAR | D21: 100 | E21: 792821.49
A22: CB-Baldwin Re Ltd. Series 2023-1 Class A Reset 2025 | C22: AEPCOTVAR | D22: 100 | E22: 749999.99
A23: CB-Baldwin Re Ltd. Series 2023-1 Class A Reset 2025 | B23: CB-Baldwin Re Ltd. Series 2023-1 Class A Reset 2025 | C23: AEPCOTVAR | D23: 100 | E23: 1500000
A24: CB-Baldwin Re Ltd. Series 2023-1 Class A Reset 2025 | B24: CB-Baldwin Re Ltd. Series 2023-1 Class A Reset 2025 | C24: AEPCOTVAR | D24: 100 | E24: 1500000
A25: CB-Baldwin Re Ltd. Series 2023-1 Class A Reset 2025 | B25: CB-Gateway Re Ltd. Series 2025-1 Class A | C25: AEPCOTVAR | D25: 100 | E25: 795818.1
A26: CB-Baldwin Re Ltd. Series 2023-1 Class A Reset 2025 | B26: CB-3264 Re Ltd. Series 2024-1 Class B Reset 2025 | C26: AEPCOTVAR | D26: 100 | E26: 764076.34
A27: CB-Baldwin Re Ltd. Series 2023-1 Class A Reset 2025 | B27: CB-Citrus Re Ltd. Series 2023-1 Class B Reset 2025 | C27: AEPCOTVAR | D27: 100 | E27: 894856.25
A28: CB-Baldwin Re Ltd. Series 2023-1 Class A Reset 2025 | B28: CB-Blue Ridge Re Ltd. Series 2023-1 Class A Reset 2025 | C28: AEPCOTVAR | D28: 100 | E28: 763579.4
A29: CB-Baldwin Re Ltd. Series 2023-1 Class A Reset 2025 | B29: CB-Bayou Re Ltd. Series 2023-1 Class A Reset 2025 | C29: AEPCOTVAR | D29: 100 | E29: 778777.34
A30: CB-Baldwin Re Ltd. Series 2023-1 Class A Reset 2025 | B30: CB-Bayou Re Ltd. Series 2023-1 Class A Reset 2025 | C30: AEPCOTVAR | D30: 100 | E30: 778777.34
A31: CB-Baldwin Re Ltd. Series 2023-1 Class A Reset 2025 | B31: CB-Bayou Re Ltd. Series 2023-1 Class B Reset 2025 | C31: AEPCOTVAR | D31: 100 | E31: 769555.77
A32: CB-Baldwin Re Ltd. Series 2023-1 Class A Reset 2025 | B32: CB-Purple Re Ltd. Series 2024-1 Class A Reset 2025 | C32: AEPCOTVAR | D32: 100 | E32: 755000.01
A33: CB-Baldwin Re Ltd. Series 2023-1 Class A Reset 2025 | B33: CB-Purple Re Ltd. Series 2023-2 Class A Reset 2025 | C33: AEPCOTVAR | D33: 100 | E33: 754999.99
A34: CB-Baldwin Re Ltd. Series 2023-1 Class A Reset 2025 | B34: CB-Bayou Re Ltd. Series 2024-1 Class A Reset 2025 | C34: AEPCOTVAR | D34: 100 | E34: 757499.99
... A41: CB-Baldwin Re Ltd. Series 2023-1 Class A Reset 2025 | B41: CB-Montoya Re Ltd. Series 2025-1 Class B Reset 2025 | C41: AEPCOTVAR | D41: 100 | E41: 792821.49
A42: CB-Gateway Re Ltd. Series 2025-1 Class A | C42: AEPCOTVAR | D42: 100 | E42: 250000
A43: CB-Gateway Re Ltd. Series 2025-1 Class A | B43: CB-Baldwin Re Ltd. Series 2023-1 Class A Reset 2025 | C43: AEPCOTVAR | D43: 100 | E43: 287500
A44: CB-Gateway Re Ltd. Series 2025-1 Class A | B44: CB-Baldwin Re Ltd. Series 2023-1 Class A Reset 2025 | C44: AEPCOTVAR | D44: 100 | E44: 287500
A45: CB-Gateway Re Ltd. Series 2025-1 Class A | B45: CB-Gateway Re Ltd. Series 2025-1 Class A | C45: AEPCOTVAR | D45: 100 | E45: 500000
A46: CB-Gateway Re Ltd. Series 2025-1 Class A | B46: CB-3264 Re Ltd. Series 2024-1 Class B Reset 2025 | C46: AEPCOTVAR | D46: 100 | E46: 455000.16
A47: CB-Gateway Re Ltd. Series 2025-1 Class A | B47: CB-Citrus Re Ltd. Series 2023-1 Class B Reset 2025 | C47: AEPCOTVAR | D47: 100 | E47: 262024.16
A48: CB-Gateway Re Ltd. Series 2025-1 Class A | B48: CB-Blue Ridge Re Ltd. Series 2023-1 Class A Reset 2025 | C48: AEPCOTVAR | D48: 100 | E48: 266545.06
A49: CB-Gateway Re Ltd. Series 2025-1 Class A | B49: CB-Bayou Re Ltd. Series 2023-1 Class A Reset 2025 | C49: AEPCOTVAR | D49: 100 | E49: 474120.94
A50: CB-Gateway Re Ltd. Series 2025-1 Class A | B50: CB-Bayou Re Ltd. Series 2023-1 Class A Reset 2025 | C50: AEPCOTVAR | D50: 100 | E50: 474120.94
A51: CB-Gateway Re Ltd. Series 2025-1 Class A | B51: CB-Bayou Re Ltd. Series 2023-1 Class B Reset 2025 | C51: AEPCOTVAR | D51: 100 | E51: 374436.37
A52: CB-Gateway Re Ltd. Series 2025-1 Class A | B52: CB-Purple Re Ltd. Series 2024-1 Class A Reset 2025 | C52: AEPCOTVAR | D52: 100 | E52: 269622.12
...

Sheet MarginalAEPMxData
A1: ILSName | B1: ILSName2 | C1: Aggtype | D1: Year | E1: AggLoss
A2: CB-Baldwin Re Ltd. Series 2023-1 Class A Reset 2025 | C2: AEPTVAR | D2: 100 | E2: 749999.99
A3: CB-Baldwin Re Ltd. Series 2023-1 Class A Reset 2025 | B3: CB-Baldwin Re Ltd. Series 2023-1 Class A Reset 2025 | C3: AEPTVAR | D3: 100 | E3: 1500000
A4: CB-Baldwin Re Ltd. Series 2023-1 Class A Reset 2025 | B4: CB-Baldwin Re Ltd. Series 2023-1 Class A Reset 2025 | C4: AEPTVAR | D4: 100 | E4: 1500000
A5: CB-Baldwin Re Ltd. Series 2023-1 Class A Reset 2025 | B5: CB-Gateway Re Ltd. Series 2025-1 Class A | C5: AEPTVAR | D5: 100 | E5: 807734.41
A6: CB-Baldwin Re Ltd. Series 2023-1 Class A Reset 2025 | B6: CB-3264 Re Ltd. Series 2024-1 Class B Reset 2025 | C6: AEPTVAR | D6: 100 | E6: 769731.55
A7: CB-Baldwin Re Ltd. Series 2023-1 Class A Reset 2025 | B7: CB-Citrus Re Ltd. Series 2023-1 Class B Reset 2025 | C7: AEPTVAR | D7: 100 | E7: 949836.26
A8: CB-Baldwin Re Ltd. Series 2023-1 Class A Reset 2025 | B8: CB-Blue Ridge Re Ltd. Series 2023-1 Class A Reset 2025 | C8: AEPTVAR | D8: 100 | E8: 768771.44
A9: CB-Baldwin Re Ltd. Series 2023-1 Class A Reset 2025 | B9: CB-Bayou Re Ltd. Series 2023-1 Class A Reset 2025 | C9: AEPTVAR | D9: 100 | E9: 788777.33
A10: CB-Baldwin Re Ltd. Series 2023-1 Class A Reset 2025 | B10: CB-Bayou Re Ltd. Series 2023-1 Class A Reset 2025 | C10: AEPTVAR | D10: 100 | E10: 788777.33
A11: CB-Baldwin Re Ltd. Series 2023-1 Class A Reset 2025 | B11: CB-Bayou Re Ltd. Series 2023-1 Class B Reset 2025 | C11: AEPTVAR | D11: 100 | E11: 776514.58
A12: CB-Baldwin Re Ltd. Series 2023-1 Class A Reset 2025 | B12: CB-Purple Re Ltd. Series 2024-1 Class A Reset 2025 | C12: AEPTVAR | D12: 100 | E12: 756515.99
A13: CB-Baldwin Re Ltd. Series 2023-1 Class A Reset 2025 | B13: CB-Purple Re Ltd. Series 2023-2 Class A Reset 2025 | C13: AEPTVAR | D13: 100 | E13: 757719.77
A14: CB-Baldwin Re Ltd. Series 2023-1 Class A Reset 2025 | B14: CB-Bayou Re Ltd. Series 2024-1 Class A Reset 2025 | C14: AEPTVAR | D14: 100 | E14: 762321.72
... A21: CB-Baldwin Re Ltd. Series 2023-1 Class A Reset 2025 | B21: CB-Montoya Re Ltd. Series 2025-1 Class B Reset 2025 | C21: AEPTVAR | D21: 100 | E21: 809301.53
A22: CB-Baldwin Re Ltd. Series 2023-1 Class A Reset 2025 | C22: AEPTVAR | D22: 100 | E22: 749999.99
A23: CB-Baldwin Re Ltd. Series 2023-1 Class A Reset 2025 | B23: CB-Baldwin Re Ltd. Series 2023-1 Class A Reset 2025 | C23: AEPTVAR | D23: 100 | E23: 1500000
A24: CB-Baldwin Re Ltd. Series 2023-1 Class A Reset 2025 | B24: CB-Baldwin Re Ltd. Series 2023-1 Class A Reset 2025 | C24: AEPTVAR | D24: 100 | E24: 1500000
A25: CB-Baldwin Re Ltd. Series 2023-1 Class A Reset 2025 | B25: CB-Gateway Re Ltd. Series 2025-1 Class A | C25: AEPTVAR | D25: 100 | E25: 807734.41
A26: CB-Baldwin Re Ltd. Series 2023-1 Class A Reset 2025 | B26: CB-3264 Re Ltd. Series 2024-1 Class B Reset 2025 | C26: AEPTVAR | D26: 100 | E26: 769731.55
A27: CB-Baldwin Re Ltd. Series 2023-1 Class A Reset 2025 | B27: CB-Citrus Re Ltd. Series 2023-1 Class B Reset 2025 | C27: AEPTVAR | D27: 100 | E27: 949836.26
A28: CB-Baldwin Re Ltd. Series 2023-1 Class A Reset 2025 | B28: CB-Blue Ridge Re Ltd. Series 2023-1 Class A Reset 2025 | C28: AEPTVAR | D28: 100 | E28: 768771.44
A29: CB-Baldwin Re Ltd. Series 2023-1 Class A Reset 2025 | B29: CB-Bayou Re Ltd. Series 2023-1 Class A Reset 2025 | C29: AEPTVAR | D29: 100 | E29: 788777.33
A30: CB-Baldwin Re Ltd. Series 2023-1 Class A Reset 2025 | B30: CB-Bayou Re Ltd. Series 2023-1 Class A Reset 2025 | C30: AEPTVAR | D30: 100 | E30: 788777.33
A31: CB-Baldwin Re Ltd. Series 2023-1 Class A Reset 2025 | B31: CB-Bayou Re Ltd. Series 2023-1 Class B Reset 2025 | C31: AEPTVAR | D31: 100 | E31: 776514.58
A32: CB-Baldwin Re Ltd. Series 2023-1 Class A Reset 2025 | B32: CB-Purple Re Ltd. Series 2024-1 Class A Reset 2025 | C32: AEPTVAR | D32: 100 | E32: 756515.99
A33: CB-Baldwin Re Ltd. Series 2023-1 Class A Reset 2025 | B33: CB-Purple Re Ltd. Series 2023-2 Class A Reset 2025 | C33: AEPTVAR | D33: 100 | E33: 757719.77
A34: CB-Baldwin Re Ltd. Series 2023-1 Class A Reset 2025 | B34: CB-Bayou Re Ltd. Series 2024-1 Class A Reset 2025 | C34: AEPTVAR | D34: 100 | E34: 762321.72
... A41: CB-Baldwin Re Ltd. Series 2023-1 Class A Reset 2025 | B41: CB-Montoya Re Ltd. Series 2025-1 Class B Reset 2025 | C41: AEPTVAR | D41: 100 | E41: 809301.53
A42: CB-Gateway Re Ltd. Series 2025-1 Class A | C42: AEPTVAR | D42: 100 | E42: 250000
A43: CB-Gateway Re Ltd. Series 2025-1 Class A | B43: CB-Baldwin Re Ltd. Series 2023-1 Class A Reset 2025 | C43: AEPTVAR | D43: 100 | E43: 807734.41
A44: CB-Gateway Re Ltd. Series 2025-1 Class A | B44: CB-Baldwin Re Ltd. Series 2023-1 Class A Reset 2025 | C44: AEPTVAR | D44: 100 | E44: 807734.41
A45: CB-Gateway Re Ltd. Series 2025-1 Class A | B45: CB-Gateway Re Ltd. Series 2025-1 Class A | C45: AEPTVAR | D45: 100 | E45: 500000
A46: CB-Gateway Re Ltd. Series 2025-1 Class A | B46: CB-3264 Re Ltd. Series 2024-1 Class B Reset 2025 | C46: AEPTVAR | D46: 100 | E46: 500000.2
A47: CB-Gateway Re Ltd. Series 2025-1 Class A | B47: CB-Citrus Re Ltd. Series 2023-1 Class B Reset 2025 | C47: AEPTVAR | D47: 100 | E47: 332045.15
A48: CB-Gateway Re Ltd. Series 2025-1 Class A | B48: CB-Blue Ridge Re Ltd. Series 2023-1 Class A Reset 2025 | C48: AEPTVAR | D48: 100 | E48: 339664.54
A49: CB-Gateway Re Ltd. Series 2025-1 Class A | B49: CB-Bayou Re Ltd. Series 2023-1 Class A Reset 2025 | C49: AEPTVAR | D49: 100 | E49: 749315.49
A50: CB-Gateway Re Ltd. Series 2025-1 Class A | B50: CB-Bayou Re Ltd. Series 2023-1 Class A Reset 2025 | C50: AEPTVAR | D50: 100 | E50: 749315.49
A51: CB-Gateway Re Ltd. Series 2025-1 Class A | B51: CB-Bayou Re Ltd. Series 2023-1 Class B Reset 2025 | C51: AEPTVAR | D51: 100 | E51: 499999.75
A52: CB-Gateway Re Ltd. Series 2025-1 Class A | B52: CB-Purple Re Ltd. Series 2024-1 Class A Reset 2025 | C52: AEPTVAR | D52: 100 | E52: 314407.14
...

Sheet Guidelines Summary
A1: Limit by Security Instrument
A2: SecurityInstrument | B2: Exposed Limit | C2: Actual % of AUM | D2: Guideline | E2: Guideline Check | F2: EL (%) | G2: AUM (%) | H2: Premium (%) | I2: Premium ($)
